Workbook

Sheet Read me
A1: Vendor questionnaire and control map (version 2)
A2: Case study | B2: Fictional learning project. Example Bank and Vendor X are placeholders. Not based on any real organisation, vendor or assessment.
A3: Purpose | B3: Stage 4 of the case study. It links each question to a control requirement, to the data flows in the architecture, and to DORA, GDPR and ISO 27001.
A4: Chain | B4: Flow or observation, then risk, then control requirement (CR), then framework reference, then question, then (Stage 5) vendor answer, finding and decision.
A5: Sheets | B5: Control requirements: 28 requirements with sources and mappings. Questionnaire: 87 questions with flow IDs and control IDs. Regulatory map: references per question. ISO 27001 view: Annex A controls this assessment tests. Summary: counts by domain.
A6: Cells to edit | B6: Yellow cells only: vendor details, and the response, evidence status, rating and notes columns on the Questionnaire sheet.
A7: Example row | B7: Row 6 (ID EX) shows the expected format and is not counted in the Summary.
A8: Flow IDs | B8: FS, FA, F3 to F12, FG, FN, FL, FH and FV refer to the data-flow table in Stage 3. All means every flow.
A9: Tier | B9: The service is Tier 1, so every question applies. Questions marked Deeper in the Regulatory map need full depth because the service supports a critical or important function.
A10: Evidence strength | B10: Strong: independent report, or system export or test dated within 90 days. Medium: dated screenshot, or policy with a small sample of records. Weak: policy only, vendor statement, or undated material.
A11: Assessor rating | B11: Satisfactory: control described and supported by strong evidence (or medium for lower-risk controls). Partial: described but evidence is weak or coverage incomplete. Gap: absent or contradicted. Not applicable: does not apply.
A12: ID note | B12: Question IDs are a domain letter plus a number (for example H1). In the traceability matrix they carry the prefix Q-, because D, F, R and S are also used for data, factors, regulations and scope.
A13: Regulatory references | B13: Article-level and indicative. Verify against the official texts. Not legal advice.
A16: Input cell | B16: Yellow fill: fill this in.

Sheet Control requirements
A1: Control requirements
A2: Each requirement is derived from the Stage 1 to 3 sources shown. Questions are IDs on the Questionnaire sheet.
A4: CR ID | B4: Area | C4: Requirement | D4: Risk addressed | E4: Derived from | F4: Questions | G4: DORA | H4: GDPR | I4: ISO 27001:2022 Annex A | J4: Other | K4: Tier
A5: CR-01 | B5: Network | C5: The vendor connects to the bank only from a fixed, documented set of source addresses, announced before any change, and the bank allows only those. | D5: An unauthorised party reaches the bank's HR, expense or finance endpoints | E5: X1; FA, F3, F6, F11, F7 | F5: H1, O1 | G5: Art 9 | H5: Art 32 | I5: A.8.20; A.8.22 | K5: All tiers
A6: CR-02 | B6: Connection authentication | C6: Every connection from the vendor into the bank uses mutual TLS or equivalent strong client authentication, with short-lived tokens. | D6: A stolen or replayed credential works from anywhere | E6: X1; V7 | F6: H2, H3, O2 | G6: Art 9 | H6: Art 32 | I6: A.8.5; A.8.24 | K6: All tiers
A7: CR-03 | B7: Credential storage | C7: Credentials the bank gives the vendor (HR, HR portal, expense and ERP accounts) are held in a vault, never in plain text, readable only by named roles, with access logged. | D7: Compromise of one place exposes four bank systems | E7: X2; V7 | F7: E3, O3 | G7: Art 9 | H7: Art 32 | I7: A.5.17; A.8.24 | K7: All tiers
A8: CR-04 | B8: Credential rotation | C8: Credentials are rotated at least every 90 days and after staff or incident triggers, and the bank can revoke them immediately. (90 days is a proposed default.) | D8: A leaked credential stays valid for months | E8: X2; V7 | F8: O4 | G8: Art 9 | H8: Art 32 | I8: A.5.17 | K8: All tiers
A9: CR-05 | B9: Connector isolation | C9: The connector is a dedicated instance for the bank, patched and monitored, with read-only access and only the agreed fields. | D9: Over-broad access allows bulk reading of employee data | E9: X1, X2; FA, F3 | F9: E1, O5, O6 | G9: Art 9 | H9: Art 5(1)(c); Art 32 | I9: A.8.22; A.8.8; A.5.15 | K9: All tiers
A10: CR-06 | B10: Connector exit | C10: At contract end the connector is shut down, credentials are revoked and deleted, and the bank receives evidence. | D10: Residual access after the relationship ends | E10: X2; Tier 1 | F10: M3, O7 | G10: Art 28(8); Art 30(2)(d) | H10: Art 28(3)(g) | I10: A.5.18; A.5.20 | K10: Tier 1
A11: CR-07 | B11: SSO and MFA | C11: Users sign in only through the bank IdP with MFA. Local passwords are disabled, including for admins, except vaulted break-glass accounts. | D11: Account takeover or unmanaged accounts | E11: X4; FS, FG, F10 | F11: B1, B2, B3, B4 | G11: Art 9 | H11: Art 32 | I11: A.5.16; A.5.17; A.8.5 | K11: All tiers
A12: CR-08 | B12: Joiners, movers, leavers | C12: Accounts follow the HR record: leavers lose access within an agreed time, movers get new roles, seats are reclaimed and access is reviewed. | D12: Former employees keep access to travel data and booking rights | E12: FA; FS | F12: C1, C2, C3, C4, C5 | G12: Art 9 | H12: Art 32 | I12: A.5.16; A.5.18; A.6.5 | K12: All tiers
A13: CR-09 | B13: Privileged and support access | C13: Vendor admin and support access to production data is just-in-time, approved, logged and restricted by region. | D13: Misuse or compromise of support accounts exposes passport and executive data | E13: X5; V8; FV | F13: D1, D2, D4 | G13: Art 9 | H13: Art 28(3)(b); Art 32 | I13: A.8.2; A.8.15 | K13: All tiers
A14: CR-10 | B14: VIP protection | C14: Executive and VIP itineraries have restricted visibility and masked trip purposes, including for vendor staff. | D14: Leak of senior management movements | E14: Stage 1 F5; S2 | F14: D5 | G14: Art 9 | H14: Art 32 | I14: A.8.3; A.5.15 | K14: All tiers
A15: CR-11 | B15: Invoice and finance integrity | C15: Invoices are authenticated and tamper-evident, duplicates and alterations are detected, and changes of bank details are verified with the bank. | D15: A fraudulent or altered invoice reaches the ERP | E15: X3; F7, F8 | F15: G1, G2, G3, G4, G5 | G15: Art 9 | H15: n/a | I15: A.8.26; A.8.32 | K15: All tiers
A16: CR-12 | B16: Data minimisation and lifecycle | C16: Only required fields are sent, retention periods are set and deletion is evidenced, test environments hold no real data, and guest data is deleted after the trip. | D16: Over-collection and long retention of passport and personal data | E16: X10; V10; D2, D3, D10 | F16: A2, E1, I3, I4, I5, I7 | G16: Art 30(2)(c); Art 30(2)(d) | H16: Art 5(1)(c); Art 5(1)(e); Art 32 | I16: A.5.34; A.8.10; A.8.33 | K16: All tiers
A17: CR-13 | B17: Encryption | C17: Data is encrypted in transit (TLS 1.2 or higher) and at rest, with defined key management and a customer-managed key option where available. | D17: Data exposed if storage or traffic is intercepted | E17: V11 | F17: H2, I1 | G17: Art 9 | H17: Art 32(1)(a) | I17: A.8.24 | K17: All tiers
A18: CR-14 | B18: Cross-border transfers and regional rules | C18: Every country that can access or receive personal data is listed with a transfer mechanism, regional residency needs are met, and local regulator requests can be supported. | D18: Unlawful transfer or breach of local data laws | E18: X5, X6; V6; R9 | F18: I2, T1, T2, T3 | G18: Art 30(2)(b) | H18: Arts 44 to 49 | I18: A.5.34; A.5.23 | J18: Regional rules (R9) | K18: All tiers
A19: CR-15 | B19: Logging and monitoring | C19: Security events are logged immutably, exportable to the bank's SIEM, free of personal and card data and monitored for anomalies. Failed syncs raise alerts. | D19: Incidents go undetected, or logs leak personal data | E19: X6; FL | F19: E4, I6, J1, J2, J3 | G19: Art 10 | H19: Art 32; Art 33(2) | I19: A.8.15; A.8.16; A.8.11 | K19: All tiers
A20: CR-16 | B20: Fourth-party transparency | C20: The vendor lists each fourth party, the data it receives and its role, gives advance notice of changes with a right to object, and ensures deletion after use. | D20: Data spreads to suppliers the bank cannot see or control | E20: X7, X12; V9; FP1 to FP10 | F20: K1, K2, K3, K4, K5 | G20: Art 28(3); Art 28(4); Art 30(2)(a) | H20: Art 28(2); Art 28(4) | I20: A.5.19; A.5.21; A.5.22 | K20: Tier 1 (deeper)
A21: CR-17 | B21: Insurer hand-off | C21: Data sent to the group insurer is accurate and minimal, health information is protected, and a failed interface is detected. | D21: Wrong or excessive data reaches the insurer, or there is no cover during a trip | E21: X8; F9 | F21: U1, U2, U3 | G21: Art 9; Art 11 | H21: Art 5(1)(d); Art 9; Art 32 | I21: A.8.26; A.5.34; A.5.30 | K21: All tiers
A22: CR-18 | B22: Allowance integrity | C22: Only authorised Finance roles change the rate table, changes are approved and logged, and calculation errors are detected before payment. | D22: Wrong or fraudulent allowance payments | E22: X9; F10, F11 | F22: D3, Q1, Q2 | G22: Art 9 | H22: n/a | I22: A.8.32; A.5.3 | J22: Allowance tax rules (R10) | K22: All tiers
A23: CR-19 | B23: Gifts and loyalty | C23: Gift orders follow value limits and recipient rules with an audit trail. Loyalty data and discount codes are protected from misuse. | D23: Improper gifts and loyalty fraud | E23: S9, S11; F5d | F23: Q3, Q4, Q5 | G23: Art 9 | H23: Art 32 | I23: A.5.3; A.5.15 | J23: Anti-bribery and gifts policy (R5) | K23: All tiers
A24: CR-20 | B24: Virtual cards | C24: Card numbers are held only where PCI DSS applies and is attested, cards are single-use with limits, and transactions are reconciled. | D24: Card misuse or card data exposure | E24: X11; V3; F12 | F24: P1, P2, P3, P4 | G24: Art 9; Art 28(4) | H24: n/a | I24: A.5.22; A.8.24 | J24: PCI DSS (R7) | K24: All tiers
A25: CR-21 | B25: Guest booking control | C25: Only authorised bookers create guest bookings with sponsor approval, and guest data is minimal and short-lived. | D25: Unauthorised bookings and uncontrolled guest data | E25: X10; S5; FG | F25: F4, I7 | G25: Art 9 | H25: Art 5(1)(c); Art 5(1)(e) | I25: A.5.3; A.5.15 | K25: All tiers
A26: CR-22 | B26: Approval integrity | C26: Approval messages are authenticated and cannot be forged or replayed, policy rules are version-controlled, and requesters cannot approve their own trips. | D26: Unapproved trips or spend | E26: F3, F6 | F26: F1, F2, F3 | G26: Art 9 | H26: n/a | I26: A.8.26; A.5.3 | K26: All tiers
A27: CR-23 | B27: Assurance evidence | C27: The vendor provides current independent assurance that covers all modules and sites: SOC 2 with a bridge letter, ISO 27001 scope, penetration test and PCI attestation. | D27: Reliance on claims or outdated reports | E27: V1 to V4 | F27: L1, L2, L3 | G27: Art 28(4); Art 30(3)(d) | H27: Art 28(1); Art 32(1)(d) | I27: A.5.22; A.8.8; A.8.29 | J27: ISO 27001 and SOC 2 (R8) | K27: Tier 1 (deeper)
A28: CR-24 | B28: Resilience and incident support | C28: Recovery targets are met and tested, incidents are notified to the bank within an agreed time, and the vendor assists at no extra cost or a set cost. | D28: A long outage or a late breach notice | E28: V5; Tier 1 | F28: M1, M2, N4 | G28: Art 11; Art 12; Art 17; Art 30(2)(e); Art 30(2)(f); Art 30(3)(a) | H28: Art 32(1)(b); Art 32(1)(c); Art 33(2) | I28: A.5.24; A.5.26; A.5.30; A.8.13; A.8.14 | K28: Tier 1 (deeper)
A29: CR-25 | B29: Contract terms | C29: The contract contains the DORA Art 30(2) terms and, because the service is Tier 1, the Art 30(3) terms, including audit rights and exit. | D29: No legal basis to enforce the controls | E29: R1; Tier 1 | F29: N1, N2, N3, N4, N5, N6, N7 | G29: Art 30(2); Art 30(3); Art 28(7) | H29: Art 28(3) | I29: A.5.20 | K29: Tier 1
A30: CR-26 | B30: Tenant isolation | C30: Customer tenants are logically separated, tested and prevented from accessing each other's data. | D30: One client sees another client's data | E30: V12; F4 | F30: I8 | G30: Art 9 | H30: Art 32 | I30: A.8.3; A.8.22 | K30: All tiers
A31: CR-27 | B31: Architecture transparency | C31: The vendor documents its edition, interfaces and data flows, keeps them current, and tells the bank about changes. | D31: The bank assesses a picture that no longer matches reality | E31: Stage 3; all flows | F31: A1, A3, E2 | G31: Art 8; Art 28(3); Art 30(2)(a) | H31: Art 30 | I31: A.5.9; A.8.20 | K31: All tiers
A32: CR-28 | B32: AI and automation | C32: AI features and model providers are disclosed, bank data is not used for model training unless agreed, and automated actions stay under human control. | D32: Bank data leaks into models, or automated actions go unchecked | E32: AI note; V13 (to add in Stage 2) | F32: W1, W2, W3 | G32: Art 28(3); Art 30(2)(a) | H32: Art 5(1)(b); Art 28(2) | I32: A.5.19; A.5.21; A.8.26 | J32: ISO/IEC 42001, EU AI Act (to check) | K32: All tiers

Sheet Questionnaire
A1: Vendor questionnaire
B2: Vendor | C2: Vendor X (fictional) | D2: Assessor
B3: Service reviewed | C3: Corporate travel management platform, Tier 1 | D3: Date
A5: ID | B5: Domain | C5: Question | D5: Flow IDs | E5: Control | F5: Evidence to request | G5: Vendor response | H5: Evidence status | I5: Assessor rating | J5: Assessor notes
A6: EX | B6: Identity and sign-on | C6: Is MFA enforced at the IdP for every login? | D6: FS | E6: CR-07 | F6: MFA policy export | G6: Yes. Enforced through conditional access for all users including admins. Two vaulted break-glass accounts are excluded. | H6: Received | I6: Satisfactory | J6: Policy export dated 15 Sep 2026 reviewed.
A7: A1 | B7: Scope and service model | C7: Is the service multi-tenant SaaS, single-tenant cloud, or self-hosted? Which edition and version are we buying? | D7: All | E7: CR-27 | F7: Architecture overview; order form showing edition | H7: Not requested
A8: A2 | B8: Scope and service model | C8: Which data categories will the service store or process (employee data, passport/ID numbers, financial data)? | D8: All | E8: CR-12 | F8: Data inventory; data-flow diagram | H8: Not requested
A9: A3 | B9: Scope and service model | C9: Which of our systems does the service connect to, and which side initiates each connection? | D9: All | E9: CR-27 | F9: Integration diagram showing trust boundaries | H9: Not requested
A10: B1 | B10: Identity and sign-on | C10: Does the service support SAML 2.0 or OIDC with our IdP, and is SSO enforced for all users? | D10: FS, FG, F10 | E10: CR-07 | F10: SSO configuration screenshot; enforcement setting | H10: Not requested
A11: B2 | B11: Identity and sign-on | C11: Can local username/password login be disabled for every user, including administrators? Which break-glass accounts exist? | D11: FS, FG, F10 | E11: CR-07 | F11: Setting screenshot; list of exceptions | H11: Not requested
A12: B3 | B12: Identity and sign-on | C12: Is MFA enforced at the IdP for every login, and how can we verify it from the service side? | D12: FS, FG, F10 | E12: CR-07 | F12: MFA / conditional access policy export | H12: Not requested
A13: B4 | B13: Identity and sign-on | C13: What session timeout, re-authentication and device or network restrictions apply? | D13: FS, FG, F10 | E13: CR-07 | F13: Session policy settings | H13: Not requested
A14: C1 | B14: Provisioning and leavers | C14: How are accounts created (SCIM, API, manual, self-signup)? Is self-signup disabled? | D14: FA, FS | E14: CR-08 | F14: Provisioning configuration; self-signup setting | H14: Not requested
A15: C2 | B15: Provisioning and leavers | C15: When the HRIS or IdP marks a user inactive, how quickly is access removed in the service? | D15: FA, FS | E15: CR-08 | F15: Leaver test with timestamps | H15: Not requested
A16: C3 | B16: Provisioning and leavers | C16: How are role changes (movers) reflected in groups, roles and entitlements? | D16: FA | E16: CR-08 | F16: Group-to-role mapping; sample mover record | H16: Not requested
A17: C4 | B17: Provisioning and leavers | C17: How are seats assigned and reclaimed, and are dormant accounts reported? | D17: FS | E17: CR-08 | F17: License report; dormant-account review | H17: Not requested
A18: C5 | B18: Provisioning and leavers | C18: How often are user access reviews performed, and who signs them off? | D18: FS | E18: CR-08 | F18: Last access review record | H18: Not requested
... A93: W3 | B93: AI and automation | C93: How are AI outputs checked so that they cannot approve spend or change records without human control? | D93: All | E93: CR-28 | F93: AI governance procedure; human-in-the-loop evidence | H93: Not requested

Sheet Regulatory map
A1: Regulatory map
A2: DORA = Regulation (EU) 2022/2554. GDPR = Regulation (EU) 2016/679. ISO = ISO/IEC 27001:2022 Annex A. Other uses the Stage 1 regulation IDs. Article-level and indicative only.
A4: ID | B4: Domain | C4: Question | D4: DORA reference | E4: DORA proportionality | F4: GDPR reference | G4: ISO 27001:2022 Annex A | H4: Other reference
A5: =Questionnaire!A7 -> A1 | B5: =Questionnaire!B7 -> Scope and service model | C5: =Questionnaire!C7 -> Is the service multi-tenant SaaS, single-tenant cloud, or self-hosted? Which edition and version are we buying? | D5: Art 28(4); Art 30(2)(a) | E5: Baseline | F5: Art 28(1) | G5: A.5.21; A.5.23
A6: =Questionnaire!A8 -> A2 | B6: =Questionnaire!B8 -> Scope and service model | C6: =Questionnaire!C8 -> Which data categories will the service store or process (employee data, passport/ID numbers, financial data)? | D6: Art 8; Art 28(3) | E6: Baseline | F6: Art 5(1)(c); Art 30 | G6: A.5.9; A.5.12
A7: =Questionnaire!A9 -> A3 | B7: =Questionnaire!B9 -> Scope and service model | C7: =Questionnaire!C9 -> Which of our systems does the service connect to, and which side initiates each connection? | D7: Art 8; Art 28(3) | E7: Baseline | F7: n/a | G7: A.5.9; A.8.20
A8: =Questionnaire!A10 -> B1 | B8: =Questionnaire!B10 -> Identity and sign-on | C8: =Questionnaire!C10 -> Does the service support SAML 2.0 or OIDC with our IdP, and is SSO enforced for all users? | D8: Art 9 | E8: Baseline | F8: Art 32 | G8: A.5.16; A.8.5
A9: =Questionnaire!A11 -> B2 | B9: =Questionnaire!B11 -> Identity and sign-on | C9: =Questionnaire!C11 -> Can local username/password login be disabled for every user, including administrators? Which break-glass accounts exist? | D9: Art 9 | E9: Baseline | F9: Art 32 | G9: A.5.17; A.8.5
A10: =Questionnaire!A12 -> B3 | B10: =Questionnaire!B12 -> Identity and sign-on | C10: =Questionnaire!C12 -> Is MFA enforced at the IdP for every login, and how can we verify it from the service side? | D10: Art 9 | E10: Baseline | F10: Art 32 | G10: A.8.5
A11: =Questionnaire!A13 -> B4 | B11: =Questionnaire!B13 -> Identity and sign-on | C11: =Questionnaire!C13 -> What session timeout, re-authentication and device or network restrictions apply? | D11: Art 9 | E11: Baseline | F11: Art 32 | G11: A.8.5; A.8.1
A12: =Questionnaire!A14 -> C1 | B12: =Questionnaire!B14 -> Provisioning and leavers | C12: =Questionnaire!C14 -> How are accounts created (SCIM, API, manual, self-signup)? Is self-signup disabled? | D12: Art 9 | E12: Baseline | F12: Art 32 | G12: A.5.16; A.5.18
A13: =Questionnaire!A15 -> C2 | B13: =Questionnaire!B15 -> Provisioning and leavers | C13: =Questionnaire!C15 -> When the HRIS or IdP marks a user inactive, how quickly is access removed in the service? | D13: Art 9 | E13: Baseline | F13: Art 32 | G13: A.5.18; A.6.5
A14: =Questionnaire!A16 -> C3 | B14: =Questionnaire!B16 -> Provisioning and leavers | C14: =Questionnaire!C16 -> How are role changes (movers) reflected in groups, roles and entitlements? | D14: Art 9 | E14: Baseline | F14: Art 32 | G14: A.5.18
A15: =Questionnaire!A17 -> C4 | B15: =Questionnaire!B17 -> Provisioning and leavers | C15: =Questionnaire!C17 -> How are seats assigned and reclaimed, and are dormant accounts reported? | D15: Art 9 | E15: Baseline | F15: n/a | G15: A.5.18
A16: =Questionnaire!A18 -> C5 | B16: =Questionnaire!B18 -> Provisioning and leavers | C16: =Questionnaire!C18 -> How often are user access reviews performed, and who signs them off? | D16: Art 9 | E16: Baseline | F16: Art 32 | G16: A.5.18
... A53: =Questionnaire!A55 -> K5 | B53: =Questionnaire!B55 -> Subprocessors | C53: =Questionnaire!C55 -> How do visa agencies and other suppliers delete or return data after the trip? | D53: Art 30(2)(d) | E53: Baseline | F53: Art 5(1)(e); Art 28(3)(g) | G53: A.8.10
A54: =Questionnaire!A56 -> L1 | B54: =Questionnaire!B56 -> Assurance | C54: =Questionnaire!C56 -> Is there a current SOC 2 Type II or ISO 27001 report whose scope covers this service? | D54: Art 28(4) | E54: Baseline | F54: Art 28(1) | G54: A.5.22 | H54: ISO 27001 and SOC 2 (R8)
A55: =Questionnaire!A57 -> L2 | B55: =Questionnaire!B57 -> Assurance | C55: =Questionnaire!C57 -> When was the last independent penetration test, and what is the remediation status? | D55: Art 28(4); Art 30(3)(d) | E55: Deeper if critical or important | F55: Art 32(1)(d) | G55: A.8.8; A.8.29
A56: =Questionnaire!A58 -> L3 | B56: =Questionnaire!B58 -> Assurance | C56: =Questionnaire!C58 -> What are the vulnerability management and patching timelines? | D56: Art 9 | E56: Baseline | F56: Art 32 | G56: A.8.8
A57: =Questionnaire!A59 -> M1 | B57: =Questionnaire!B59 -> Resilience and exit | C57: =Questionnaire!C59 -> What are the RTO, RPO and uptime SLA, and when was disaster recovery last tested? | D57: Art 11; Art 12; Art 30(2)(e) | E57: Deeper if critical or important | F57: Art 32(1)(b); Art 32(1)(c) | G57: A.5.30; A.8.13; A.8.14
A58: =Questionnaire!A60 -> M2 | B58: =Questionnaire!B60 -> Resilience and exit | C58: =Questionnaire!C60 -> What is the breach notification commitment and process? | D58: Art 17; Art 30(2)(f) | E58: Baseline | F58: Art 33(2) | G58: A.5.24; A.5.26
A59: =Questionnaire!A61 -> M3 | B59: =Questionnaire!B61 -> Resilience and exit | C59: =Questionnaire!C61 -> What is the exit plan (data export formats, transition support) and our manual fallback if the vendor is unavailable? | D59: Art 28(7); Art 28(8); Art 30(3)(f) | E59: Deeper if critical or important | F59: n/a | G59: A.5.23
A60: =Questionnaire!A62 -> N1 | B60: =Questionnaire!B62 -> Contract terms | C60: =Questionnaire!C62 -> Does the contract fully describe the services, the functions supported, and the conditions for subcontracting? | D60: Art 30(2)(a) | E60: Baseline | F60: Art 28(3) | G60: A.5.20
A61: =Questionnaire!A63 -> N2 | B61: =Questionnaire!B63 -> Contract terms | C61: =Questionnaire!C63 -> Does the vendor commit to cooperate with our competent and resolution authorities? | D61: Art 30(2)(g) | E61: Baseline | F61: Art 31 | G61: A.5.20
A62: =Questionnaire!A64 -> N3 | B62: =Questionnaire!B64 -> Contract terms | C62: =Questionnaire!C64 -> What termination rights and minimum notice periods does the contract provide? | D62: Art 28(7); Art 30(2)(h) | E62: Baseline | F62: n/a | G62: A.5.20
A63: =Questionnaire!A65 -> N4 | B63: =Questionnaire!B65 -> Contract terms | C63: =Questionnaire!C65 -> Does the vendor assist with ICT incidents at no extra cost or at a predetermined cost? | D63: Art 30(2)(f) | E63: Baseline | F63: Art 28(3)(f) | G63: A.5.20; A.5.26
A64: =Questionnaire!A66 -> N5 | B64: =Questionnaire!B66 -> Contract terms | C64: =Questionnaire!C66 -> Does the contract guarantee access to, recovery and return of our data if the vendor becomes insolvent or stops the service? | D64: Art 30(2)(d) | E64: Baseline | F64: Art 28(3)(g) | G64: A.5.20
A65: =Questionnaire!A67 -> N6 | B65: =Questionnaire!B67 -> Contract terms | C65: =Questionnaire!C67 -> Will the vendor take part in our security awareness and resilience training where required? | D65: Art 30(2)(i) | E65: Baseline | F65: n/a | G65: A.5.20; A.6.3
A66: =Questionnaire!A68 -> N7 | B66: =Questionnaire!B68 -> Contract terms | C66: =Questionnaire!C68 -> Does the contract give us rights of access, inspection and audit over the service? | D66: Art 30(3)(e) | E66: Deeper if critical or important | F66: Art 28(3)(h) | G66: A.5.22
... A73: =Questionnaire!A75 -> O7 | B73: =Questionnaire!B75 -> Connector and credentials | C73: =Questionnaire!C75 -> What happens to the connector and our credentials at contract end, and how is deletion evidenced? | D73: Art 28(8); Art 30(2)(d) | E73: Deeper if critical or important | F73: Art 28(3)(g) | G73: A.5.18; A.5.20
A74: =Questionnaire!A76 -> P1 | B74: =Questionnaire!B76 -> Virtual cards | C74: =Questionnaire!C76 -> Which party stores or processes card numbers, and does each hold a current PCI DSS attestation that covers this service? | D74: Art 9; Art 28(4) | E74: Baseline | F74: n/a | G74: A.5.22; A.8.24 | H74: PCI DSS (R7)
A75: =Questionnaire!A77 -> P2 | B75: =Questionnaire!B77 -> Virtual cards | C75: =Questionnaire!C77 -> Are virtual cards single-use with a spending limit per booking, and who can change the limits? | D75: Art 9 | E75: Baseline | F75: n/a | G75: A.8.3 | H75: PCI DSS (R7)
A76: =Questionnaire!A78 -> P3 | B76: =Questionnaire!B78 -> Virtual cards | C76: =Questionnaire!C78 -> Does the platform hold full card numbers or only tokens, and how are numbers protected when shown to users? | D76: Art 9 | E76: Baseline | F76: n/a | G76: A.8.24; A.8.11 | H76: PCI DSS (R7)
A77: =Questionnaire!A79 -> P4 | B77: =Questionnaire!B79 -> Virtual cards | C77: =Questionnaire!C79 -> How are card transactions reconciled to bookings and to the monthly invoice, and how are disputes handled? | D77: Art 9 | E77: Baseline | F77: n/a | G77: A.8.26 | H77: PCI DSS (R7)
A78: =Questionnaire!A80 -> Q1 | B78: =Questionnaire!B80 -> Allowance, gifts and loyalty | C78: =Questionnaire!C80 -> Who can change the daily allowance rate table, and how are changes approved, logged and made visible to Finance? | D78: Art 9 | E78: Baseline | F78: n/a | G78: A.8.32; A.5.3 | H78: Allowance tax rules (R10)
A79: =Questionnaire!A81 -> Q2 | B79: =Questionnaire!B81 -> Allowance, gifts and loyalty | C79: =Questionnaire!C81 -> How is the allowance calculated, and how are calculation errors detected before the amount reaches payroll or the expense system? | D79: Art 9 | E79: Baseline | F79: n/a | G79: A.8.26 | H79: Allowance tax rules (R10)
A80: =Questionnaire!A82 -> Q3 | B80: =Questionnaire!B82 -> Allowance, gifts and loyalty | C80: =Questionnaire!C82 -> How are gift and flower orders checked against value limits and recipient restrictions, and how is the audit trail kept? | D80: Art 9 | E80: Baseline | F80: Art 5(1)(c) | G80: A.5.3; A.8.15 | H80: Anti-bribery and gifts policy (R5)
A81: =Questionnaire!A83 -> Q4 | B81: =Questionnaire!B83 -> Allowance, gifts and loyalty | C81: =Questionnaire!C83 -> How are loyalty and frequent flyer numbers stored, and who can see or use them? | D81: Art 9 | E81: Baseline | F81: Art 32 | G81: A.5.34; A.8.3
A82: =Questionnaire!A84 -> Q5 | B82: =Questionnaire!B84 -> Allowance, gifts and loyalty | C82: =Questionnaire!C84 -> How are discount codes and corporate rates protected from misuse? | D82: Art 9 | E82: Baseline | F82: n/a | G82: A.5.15
A83: =Questionnaire!A85 -> T1 | B83: =Questionnaire!B85 -> Regional and transfers | C83: =Questionnaire!C85 -> Which countries can access or receive personal data (support, subprocessors, suppliers), and what transfer mechanism applies to each? | D83: Art 30(2)(b) | E83: Baseline | F83: Arts 44 to 49 | G83: A.5.34; A.5.23 | H83: Regional rules (R9)
...

Sheet ISO 27001 view
A1: ISO 27001 view
A2: Annex A controls (ISO/IEC 27001:2022) that this assessment tests. This is a coverage view, not a Statement of Applicability for the bank.
A4: Annex A control | B4: Title | C4: Theme | D4: Control requirements | E4: Questions | F4: Evidence expected (first three)
A5: A.5.3 | B5: Segregation of duties | C5: Organizational | D5: CR-18, CR-19, CR-21, CR-22, CR-28 | E5: D3, F3, F4, Q1, Q3, W3 | F5: Role matrix; change log extract; Test result or configuration evidence; Role configuration; guest booking workflow test
A6: A.5.9 | B6: Inventory of information and other associated assets | C6: Organizational | D6: CR-12, CR-27 | E6: A2, A3 | F6: Data inventory; data-flow diagram; Integration diagram showing trust boundaries
A7: A.5.12 | B7: Classification of information | C7: Organizational | D7: CR-12 | E7: A2 | F7: Data inventory; data-flow diagram
A8: A.5.14 | B8: Information transfer | C8: Organizational | D8: CR-27 | E8: E2 | F8: Interface specification
A9: A.5.15 | B9: Access control | C9: Organizational | D9: CR-05, CR-09, CR-10, CR-11, CR-19, CR-21 | E9: D1, D5, F4, G1, O6, Q5 | F9: Admin list; admin role model; VIP profile configuration; access test result; Role configuration; guest booking workflow test
A10: A.5.16 | B10: Identity management | C10: Organizational | D10: CR-07, CR-08 | E10: B1, C1 | F10: SSO configuration screenshot; enforcement setting; Provisioning configuration; self-signup setting
A11: A.5.17 | B11: Authentication information | C11: Organizational | D11: CR-03, CR-04, CR-07 | E11: B2, O3, O4 | F11: Setting screenshot; list of exceptions; Secrets management procedure; access list; Rotation schedule; revocation test
A12: A.5.18 | B12: Access rights | C12: Organizational | D12: CR-06, CR-08 | E12: C1, C2, C3, C4, C5, O7 | F12: Provisioning configuration; self-signup setting; Leaver test with timestamps; Group-to-role mapping; sample mover record
A13: A.5.19 | B13: Information security in supplier relationships | C13: Organizational | D13: CR-09, CR-16, CR-28 | E13: D2, K1, K3, W1 | F13: Support access policy; sample access log; Subprocessor list; Data-sharing register
A14: A.5.20 | B14: Addressing information security within supplier agreements | C14: Organizational | D14: CR-06, CR-24, CR-25 | E14: N1, N2, N3, N4, N5, N6, O7 | F14: Contract and service description; Contract clause; Contract clause; price schedule
A15: A.5.21 | B15: Managing information security in the ICT supply chain | C15: Organizational | D15: CR-16, CR-27, CR-28 | E15: A1, K1, W1 | F15: Architecture overview; order form showing edition; Subprocessor list; AI feature inventory; model provider list
... A43: A.8.33 | B43: Test information | C43: Technological | D43: CR-12, CR-28 | E43: I5, W2 | F43: Written policy statement; contract clause; Contract clause; data-use statement

Sheet Summary
A1: Assessment summary
A2: Counts update from the Questionnaire sheet (example row excluded).
A4: Domain | B4: Questions | C4: Satisfactory | D4: Partial | E4: Gap | F4: Not applicable | G4: Not yet rated | H4: Evidence accepted
A5: Scope and service model | B5: =COUNTIF(Questionnaire!$B$7:$B$93,$A5) -> 3 | C5: =COUNTIFS(Questionnaire!$B$7:$B$93,$A5,Questionnaire!$I$7:$I$93,"Satisfactory") -> 0 | D5: =COUNTIFS(Questionnaire!$B$7:$B$93,$A5,Questionnaire!$I$7:$I$93,"Partial") -> 0 | E5: =COUNTIFS(Questionnaire!$B$7:$B$93,$A5,Questionnaire!$I$7:$I$93,"Gap") -> 0 | F5: =COUNTIFS(Questionnaire!$B$7:$B$93,$A5,Questionnaire!$I$7:$I$93,"Not applicable") -> 0 | G5: =B5-SUM(C5:F5) -> 3 | H5: =COUNTIFS(Questionnaire!$B$7:$B$93,$A5,Questionnaire!$H$7:$H$93,"Accepted") -> 0
A6: Identity and sign-on | B6: =COUNTIF(Questionnaire!$B$7:$B$93,$A6) -> 4 | C6: =COUNTIFS(Questionnaire!$B$7:$B$93,$A6,Questionnaire!$I$7:$I$93,"Satisfactory") -> 0 | D6: =COUNTIFS(Questionnaire!$B$7:$B$93,$A6,Questionnaire!$I$7:$I$93,"Partial") -> 0 | E6: =COUNTIFS(Questionnaire!$B$7:$B$93,$A6,Questionnaire!$I$7:$I$93,"Gap") -> 0 | F6: =COUNTIFS(Questionnaire!$B$7:$B$93,$A6,Questionnaire!$I$7:$I$93,"Not applicable") -> 0 | G6: =B6-SUM(C6:F6) -> 4 | H6: =COUNTIFS(Questionnaire!$B$7:$B$93,$A6,Questionnaire!$H$7:$H$93,"Accepted") -> 0
A7: Provisioning and leavers | B7: =COUNTIF(Questionnaire!$B$7:$B$93,$A7) -> 5 | C7: =COUNTIFS(Questionnaire!$B$7:$B$93,$A7,Questionnaire!$I$7:$I$93,"Satisfactory") -> 0 | D7: =COUNTIFS(Questionnaire!$B$7:$B$93,$A7,Questionnaire!$I$7:$I$93,"Partial") -> 0 | E7: =COUNTIFS(Questionnaire!$B$7:$B$93,$A7,Questionnaire!$I$7:$I$93,"Gap") -> 0 | F7: =COUNTIFS(Questionnaire!$B$7:$B$93,$A7,Questionnaire!$I$7:$I$93,"Not applicable") -> 0 | G7: =B7-SUM(C7:F7) -> 5 | H7: =COUNTIFS(Questionnaire!$B$7:$B$93,$A7,Questionnaire!$H$7:$H$93,"Accepted") -> 0
A8: Administration and access | B8: =COUNTIF(Questionnaire!$B$7:$B$93,$A8) -> 5 | C8: =COUNTIFS(Questionnaire!$B$7:$B$93,$A8,Questionnaire!$I$7:$I$93,"Satisfactory") -> 0 | D8: =COUNTIFS(Questionnaire!$B$7:$B$93,$A8,Questionnaire!$I$7:$I$93,"Partial") -> 0 | E8: =COUNTIFS(Questionnaire!$B$7:$B$93,$A8,Questionnaire!$I$7:$I$93,"Gap") -> 0 | F8: =COUNTIFS(Questionnaire!$B$7:$B$93,$A8,Questionnaire!$I$7:$I$93,"Not applicable") -> 0 | G8: =B8-SUM(C8:F8) -> 5 | H8: =COUNTIFS(Questionnaire!$B$7:$B$93,$A8,Questionnaire!$H$7:$H$93,"Accepted") -> 0
A9: HR data sync | B9: =COUNTIF(Questionnaire!$B$7:$B$93,$A9) -> 4 | C9: =COUNTIFS(Questionnaire!$B$7:$B$93,$A9,Questionnaire!$I$7:$I$93,"Satisfactory") -> 0 | D9: =COUNTIFS(Questionnaire!$B$7:$B$93,$A9,Questionnaire!$I$7:$I$93,"Partial") -> 0 | E9: =COUNTIFS(Questionnaire!$B$7:$B$93,$A9,Questionnaire!$I$7:$I$93,"Gap") -> 0 | F9: =COUNTIFS(Questionnaire!$B$7:$B$93,$A9,Questionnaire!$I$7:$I$93,"Not applicable") -> 0 | G9: =B9-SUM(C9:F9) -> 4 | H9: =COUNTIFS(Questionnaire!$B$7:$B$93,$A9,Questionnaire!$H$7:$H$93,"Accepted") -> 0
A10: Approvals and policy | B10: =COUNTIF(Questionnaire!$B$7:$B$93,$A10) -> 4 | C10: =COUNTIFS(Questionnaire!$B$7:$B$93,$A10,Questionnaire!$I$7:$I$93,"Satisfactory") -> 0 | D10: =COUNTIFS(Questionnaire!$B$7:$B$93,$A10,Questionnaire!$I$7:$I$93,"Partial") -> 0 | E10: =COUNTIFS(Questionnaire!$B$7:$B$93,$A10,Questionnaire!$I$7:$I$93,"Gap") -> 0 | F10: =COUNTIFS(Questionnaire!$B$7:$B$93,$A10,Questionnaire!$I$7:$I$93,"Not applicable") -> 0 | G10: =B10-SUM(C10:F10) -> 4 | H10: =COUNTIFS(Questionnaire!$B$7:$B$93,$A10,Questionnaire!$H$7:$H$93,"Accepted") -> 0
A11: Financial sync | B11: =COUNTIF(Questionnaire!$B$7:$B$93,$A11) -> 5 | C11: =COUNTIFS(Questionnaire!$B$7:$B$93,$A11,Questionnaire!$I$7:$I$93,"Satisfactory") -> 0 | D11: =COUNTIFS(Questionnaire!$B$7:$B$93,$A11,Questionnaire!$I$7:$I$93,"Partial") -> 0 | E11: =COUNTIFS(Questionnaire!$B$7:$B$93,$A11,Questionnaire!$I$7:$I$93,"Gap") -> 0 | F11: =COUNTIFS(Questionnaire!$B$7:$B$93,$A11,Questionnaire!$I$7:$I$93,"Not applicable") -> 0 | G11: =B11-SUM(C11:F11) -> 5 | H11: =COUNTIFS(Questionnaire!$B$7:$B$93,$A11,Questionnaire!$H$7:$H$93,"Accepted") -> 0
A12: Network and gateway | B12: =COUNTIF(Questionnaire!$B$7:$B$93,$A12) -> 3 | C12: =COUNTIFS(Questionnaire!$B$7:$B$93,$A12,Questionnaire!$I$7:$I$93,"Satisfactory") -> 0 | D12: =COUNTIFS(Questionnaire!$B$7:$B$93,$A12,Questionnaire!$I$7:$I$93,"Partial") -> 0 | E12: =COUNTIFS(Questionnaire!$B$7:$B$93,$A12,Questionnaire!$I$7:$I$93,"Gap") -> 0 | F12: =COUNTIFS(Questionnaire!$B$7:$B$93,$A12,Questionnaire!$I$7:$I$93,"Not applicable") -> 0 | G12: =B12-SUM(C12:F12) -> 3 | H12: =COUNTIFS(Questionnaire!$B$7:$B$93,$A12,Questionnaire!$H$7:$H$93,"Accepted") -> 0
A13: Data protection | B13: =COUNTIF(Questionnaire!$B$7:$B$93,$A13) -> 8 | C13: =COUNTIFS(Questionnaire!$B$7:$B$93,$A13,Questionnaire!$I$7:$I$93,"Satisfactory") -> 0 | D13: =COUNTIFS(Questionnaire!$B$7:$B$93,$A13,Questionnaire!$I$7:$I$93,"Partial") -> 0 | E13: =COUNTIFS(Questionnaire!$B$7:$B$93,$A13,Questionnaire!$I$7:$I$93,"Gap") -> 0 | F13: =COUNTIFS(Questionnaire!$B$7:$B$93,$A13,Questionnaire!$I$7:$I$93,"Not applicable") -> 0 | G13: =B13-SUM(C13:F13) -> 8 | H13: =COUNTIFS(Questionnaire!$B$7:$B$93,$A13,Questionnaire!$H$7:$H$93,"Accepted") -> 0
A14: Logging and monitoring | B14: =COUNTIF(Questionnaire!$B$7:$B$93,$A14) -> 3 | C14: =COUNTIFS(Questionnaire!$B$7:$B$93,$A14,Questionnaire!$I$7:$I$93,"Satisfactory") -> 0 | D14: =COUNTIFS(Questionnaire!$B$7:$B$93,$A14,Questionnaire!$I$7:$I$93,"Partial") -> 0 | E14: =COUNTIFS(Questionnaire!$B$7:$B$93,$A14,Questionnaire!$I$7:$I$93,"Gap") -> 0 | F14: =COUNTIFS(Questionnaire!$B$7:$B$93,$A14,Questionnaire!$I$7:$I$93,"Not applicable") -> 0 | G14: =B14-SUM(C14:F14) -> 3 | H14: =COUNTIFS(Questionnaire!$B$7:$B$93,$A14,Questionnaire!$H$7:$H$93,"Accepted") -> 0
A15: Subprocessors | B15: =COUNTIF(Questionnaire!$B$7:$B$93,$A15) -> 5 | C15: =COUNTIFS(Questionnaire!$B$7:$B$93,$A15,Questionnaire!$I$7:$I$93,"Satisfactory") -> 0 | D15: =COUNTIFS(Questionnaire!$B$7:$B$93,$A15,Questionnaire!$I$7:$I$93,"Partial") -> 0 | E15: =COUNTIFS(Questionnaire!$B$7:$B$93,$A15,Questionnaire!$I$7:$I$93,"Gap") -> 0 | F15: =COUNTIFS(Questionnaire!$B$7:$B$93,$A15,Questionnaire!$I$7:$I$93,"Not applicable") -> 0 | G15: =B15-SUM(C15:F15) -> 5 | H15: =COUNTIFS(Questionnaire!$B$7:$B$93,$A15,Questionnaire!$H$7:$H$93,"Accepted") -> 0
A16: Assurance | B16: =COUNTIF(Questionnaire!$B$7:$B$93,$A16) -> 3 | C16: =COUNTIFS(Questionnaire!$B$7:$B$93,$A16,Questionnaire!$I$7:$I$93,"Satisfactory") -> 0 | D16: =COUNTIFS(Questionnaire!$B$7:$B$93,$A16,Questionnaire!$I$7:$I$93,"Partial") -> 0 | E16: =COUNTIFS(Questionnaire!$B$7:$B$93,$A16,Questionnaire!$I$7:$I$93,"Gap") -> 0 | F16: =COUNTIFS(Questionnaire!$B$7:$B$93,$A16,Questionnaire!$I$7:$I$93,"Not applicable") -> 0 | G16: =B16-SUM(C16:F16) -> 3 | H16: =COUNTIFS(Questionnaire!$B$7:$B$93,$A16,Questionnaire!$H$7:$H$93,"Accepted") -> 0
... A24: AI and automation | B24: =COUNTIF(Questionnaire!$B$7:$B$93,$A24) -> 3 | C24: =COUNTIFS(Questionnaire!$B$7:$B$93,$A24,Questionnaire!$I$7:$I$93,"Satisfactory") -> 0 | D24: =COUNTIFS(Questionnaire!$B$7:$B$93,$A24,Questionnaire!$I$7:$I$93,"Partial") -> 0 | E24: =COUNTIFS(Questionnaire!$B$7:$B$93,$A24,Questionnaire!$I$7:$I$93,"Gap") -> 0 | F24: =COUNTIFS(Questionnaire!$B$7:$B$93,$A24,Questionnaire!$I$7:$I$93,"Not applicable") -> 0 | G24: =B24-SUM(C24:F24) -> 3 | H24: =COUNTIFS(Questionnaire!$B$7:$B$93,$A24,Questionnaire!$H$7:$H$93,"Accepted") -> 0
A25: Total | B25: =SUM(B5:B24) -> 87 | C25: =SUM(C5:C24) -> 0 | D25: =SUM(D5:D24) -> 0 | E25: =SUM(E5:E24) -> 0 | F25: =SUM(F5:F24) -> 0 | G25: =SUM(G5:G24) -> 87 | H25: =SUM(H5:H24) -> 0
