Workbook

Sheet Read me
A1: Follow-up workbook (simulated)
A2: Case study | B2: Fictional. Example Bank and Vendor X are placeholders. All vendor answers, evidence, dates and scores are simulated.
A3: Purpose | B3: The follow-up to the initial vendor assessment: the bank's follow-up questions, the vendor's simulated replies, the re-rating of findings and risks, and the status of the go-live conditions.
A4: Initial assessment | B4: Folders 01 to 05 are unchanged. This workbook records what moved, what stayed and what is new.
A5: Timeline | B5: Request issued 12 Oct 2026. First vendor reply 6 Nov 2026. Second evidence batch 27 Nov 2026. Re-assessment closed 4 Dec 2026. Risk committee 11 Dec 2026. Conditions due 15 Jan 2027. Go-live target 1 Feb 2027.
A6: Sheets | B6: Summary, Findings, Risk register (four scores), Conditions, New actions, Follow-up questions (65), Re-asked (23 questions left unassessed in the initial assessment), Evidence log, Bank actions, Outside-in checks, Not requested, Controls (new), Regulatory map, ISO view (follow-up).
A7: IDs | B7: Follow-up questions: FU-AREA-NN (for example FU-IAM-01). In the traceability matrix they carry the prefix Q-. New: FND-23 to FND-33, REM-23 to REM-33, RR-18 to RR-21, EV-26 to EV-66, CR-29 to CR-33, BA-nn (bank actions), OS-nn (outside-in checks).
A8: Reply types | B8: Full, Partial, Declined, No reply describe the vendor's reply. Rating (Satisfactory, Partial, Gap, Not assessed) describes the assessor's view of the answer and the evidence.
A9: Four risk scores | B9: Inherent (before vendor controls), Initial current, Verified after the follow-up, Target. Risk falls only when evidence is verified, not when the vendor promises something.
A10: Decision rules | B10: Unchanged from the initial assessment: High findings closed before go-live, Medium within 90 days, a missing mandatory contract term for a critical service counts as High.
A11: Not legal advice | B11: Regulatory references are indicative. Verify against the official texts.
A14: Input cell | B14: Yellow fill: fill this in.

Sheet Summary
A1: Follow-up summary
A2: All figures are formulas on the other sheets.
A4: Follow-up questions by area | B4: Questions | C4: Satisfactory | D4: Partial | E4: Gap | F4: Not assessed
A5: Identity and access management | B5: =COUNTIF('Follow-up questions'!$B$4:$B$68,$A5) -> 5 | C5: =COUNTIFS('Follow-up questions'!$B$4:$B$68,$A5,'Follow-up questions'!$K$4:$K$68,"Satisfactory") -> 3 | D5: =COUNTIFS('Follow-up questions'!$B$4:$B$68,$A5,'Follow-up questions'!$K$4:$K$68,"Partial") -> 2 | E5: =COUNTIFS('Follow-up questions'!$B$4:$B$68,$A5,'Follow-up questions'!$K$4:$K$68,"Gap") -> 0 | F5: =COUNTIFS('Follow-up questions'!$B$4:$B$68,$A5,'Follow-up questions'!$K$4:$K$68,"Not assessed") -> 0
A6: Data security | B6: =COUNTIF('Follow-up questions'!$B$4:$B$68,$A6) -> 4 | C6: =COUNTIFS('Follow-up questions'!$B$4:$B$68,$A6,'Follow-up questions'!$K$4:$K$68,"Satisfactory") -> 1 | D6: =COUNTIFS('Follow-up questions'!$B$4:$B$68,$A6,'Follow-up questions'!$K$4:$K$68,"Partial") -> 2 | E6: =COUNTIFS('Follow-up questions'!$B$4:$B$68,$A6,'Follow-up questions'!$K$4:$K$68,"Gap") -> 1 | F6: =COUNTIFS('Follow-up questions'!$B$4:$B$68,$A6,'Follow-up questions'!$K$4:$K$68,"Not assessed") -> 0
A7: Cryptography and key management | B7: =COUNTIF('Follow-up questions'!$B$4:$B$68,$A7) -> 3 | C7: =COUNTIFS('Follow-up questions'!$B$4:$B$68,$A7,'Follow-up questions'!$K$4:$K$68,"Satisfactory") -> 1 | D7: =COUNTIFS('Follow-up questions'!$B$4:$B$68,$A7,'Follow-up questions'!$K$4:$K$68,"Partial") -> 1 | E7: =COUNTIFS('Follow-up questions'!$B$4:$B$68,$A7,'Follow-up questions'!$K$4:$K$68,"Gap") -> 1 | F7: =COUNTIFS('Follow-up questions'!$B$4:$B$68,$A7,'Follow-up questions'!$K$4:$K$68,"Not assessed") -> 0
A8: Application security | B8: =COUNTIF('Follow-up questions'!$B$4:$B$68,$A8) -> 7 | C8: =COUNTIFS('Follow-up questions'!$B$4:$B$68,$A8,'Follow-up questions'!$K$4:$K$68,"Satisfactory") -> 2 | D8: =COUNTIFS('Follow-up questions'!$B$4:$B$68,$A8,'Follow-up questions'!$K$4:$K$68,"Partial") -> 5 | E8: =COUNTIFS('Follow-up questions'!$B$4:$B$68,$A8,'Follow-up questions'!$K$4:$K$68,"Gap") -> 0 | F8: =COUNTIFS('Follow-up questions'!$B$4:$B$68,$A8,'Follow-up questions'!$K$4:$K$68,"Not assessed") -> 0
A9: Cloud security | B9: =COUNTIF('Follow-up questions'!$B$4:$B$68,$A9) -> 4 | C9: =COUNTIFS('Follow-up questions'!$B$4:$B$68,$A9,'Follow-up questions'!$K$4:$K$68,"Satisfactory") -> 3 | D9: =COUNTIFS('Follow-up questions'!$B$4:$B$68,$A9,'Follow-up questions'!$K$4:$K$68,"Partial") -> 0 | E9: =COUNTIFS('Follow-up questions'!$B$4:$B$68,$A9,'Follow-up questions'!$K$4:$K$68,"Gap") -> 1 | F9: =COUNTIFS('Follow-up questions'!$B$4:$B$68,$A9,'Follow-up questions'!$K$4:$K$68,"Not assessed") -> 0
A10: Network security | B10: =COUNTIF('Follow-up questions'!$B$4:$B$68,$A10) -> 3 | C10: =COUNTIFS('Follow-up questions'!$B$4:$B$68,$A10,'Follow-up questions'!$K$4:$K$68,"Satisfactory") -> 3 | D10: =COUNTIFS('Follow-up questions'!$B$4:$B$68,$A10,'Follow-up questions'!$K$4:$K$68,"Partial") -> 0 | E10: =COUNTIFS('Follow-up questions'!$B$4:$B$68,$A10,'Follow-up questions'!$K$4:$K$68,"Gap") -> 0 | F10: =COUNTIFS('Follow-up questions'!$B$4:$B$68,$A10,'Follow-up questions'!$K$4:$K$68,"Not assessed") -> 0
A11: Third-party risk | B11: =COUNTIF('Follow-up questions'!$B$4:$B$68,$A11) -> 4 | C11: =COUNTIFS('Follow-up questions'!$B$4:$B$68,$A11,'Follow-up questions'!$K$4:$K$68,"Satisfactory") -> 0 | D11: =COUNTIFS('Follow-up questions'!$B$4:$B$68,$A11,'Follow-up questions'!$K$4:$K$68,"Partial") -> 3 | E11: =COUNTIFS('Follow-up questions'!$B$4:$B$68,$A11,'Follow-up questions'!$K$4:$K$68,"Gap") -> 0 | F11: =COUNTIFS('Follow-up questions'!$B$4:$B$68,$A11,'Follow-up questions'!$K$4:$K$68,"Not assessed") -> 1
A12: AI security | B12: =COUNTIF('Follow-up questions'!$B$4:$B$68,$A12) -> 4 | C12: =COUNTIFS('Follow-up questions'!$B$4:$B$68,$A12,'Follow-up questions'!$K$4:$K$68,"Satisfactory") -> 1 | D12: =COUNTIFS('Follow-up questions'!$B$4:$B$68,$A12,'Follow-up questions'!$K$4:$K$68,"Partial") -> 2 | E12: =COUNTIFS('Follow-up questions'!$B$4:$B$68,$A12,'Follow-up questions'!$K$4:$K$68,"Gap") -> 1 | F12: =COUNTIFS('Follow-up questions'!$B$4:$B$68,$A12,'Follow-up questions'!$K$4:$K$68,"Not assessed") -> 0
A13: Vulnerability and security testing | B13: =COUNTIF('Follow-up questions'!$B$4:$B$68,$A13) -> 3 | C13: =COUNTIFS('Follow-up questions'!$B$4:$B$68,$A13,'Follow-up questions'!$K$4:$K$68,"Satisfactory") -> 1 | D13: =COUNTIFS('Follow-up questions'!$B$4:$B$68,$A13,'Follow-up questions'!$K$4:$K$68,"Partial") -> 1 | E13: =COUNTIFS('Follow-up questions'!$B$4:$B$68,$A13,'Follow-up questions'!$K$4:$K$68,"Gap") -> 1 | F13: =COUNTIFS('Follow-up questions'!$B$4:$B$68,$A13,'Follow-up questions'!$K$4:$K$68,"Not assessed") -> 0
A14: Security monitoring | B14: =COUNTIF('Follow-up questions'!$B$4:$B$68,$A14) -> 3 | C14: =COUNTIFS('Follow-up questions'!$B$4:$B$68,$A14,'Follow-up questions'!$K$4:$K$68,"Satisfactory") -> 2 | D14: =COUNTIFS('Follow-up questions'!$B$4:$B$68,$A14,'Follow-up questions'!$K$4:$K$68,"Partial") -> 1 | E14: =COUNTIFS('Follow-up questions'!$B$4:$B$68,$A14,'Follow-up questions'!$K$4:$K$68,"Gap") -> 0 | F14: =COUNTIFS('Follow-up questions'!$B$4:$B$68,$A14,'Follow-up questions'!$K$4:$K$68,"Not assessed") -> 0
A15: Incident response | B15: =COUNTIF('Follow-up questions'!$B$4:$B$68,$A15) -> 4 | C15: =COUNTIFS('Follow-up questions'!$B$4:$B$68,$A15,'Follow-up questions'!$K$4:$K$68,"Satisfactory") -> 1 | D15: =COUNTIFS('Follow-up questions'!$B$4:$B$68,$A15,'Follow-up questions'!$K$4:$K$68,"Partial") -> 3 | E15: =COUNTIFS('Follow-up questions'!$B$4:$B$68,$A15,'Follow-up questions'!$K$4:$K$68,"Gap") -> 0 | F15: =COUNTIFS('Follow-up questions'!$B$4:$B$68,$A15,'Follow-up questions'!$K$4:$K$68,"Not assessed") -> 0
A16: Business continuity and disaster recovery | B16: =COUNTIF('Follow-up questions'!$B$4:$B$68,$A16) -> 4 | C16: =COUNTIFS('Follow-up questions'!$B$4:$B$68,$A16,'Follow-up questions'!$K$4:$K$68,"Satisfactory") -> 2 | D16: =COUNTIFS('Follow-up questions'!$B$4:$B$68,$A16,'Follow-up questions'!$K$4:$K$68,"Partial") -> 1 | E16: =COUNTIFS('Follow-up questions'!$B$4:$B$68,$A16,'Follow-up questions'!$K$4:$K$68,"Gap") -> 1 | F16: =COUNTIFS('Follow-up questions'!$B$4:$B$68,$A16,'Follow-up questions'!$K$4:$K$68,"Not assessed") -> 0
... A22: Physical security | B22: =COUNTIF('Follow-up questions'!$B$4:$B$68,$A22) -> 2 | C22: =COUNTIFS('Follow-up questions'!$B$4:$B$68,$A22,'Follow-up questions'!$K$4:$K$68,"Satisfactory") -> 0 | D22: =COUNTIFS('Follow-up questions'!$B$4:$B$68,$A22,'Follow-up questions'!$K$4:$K$68,"Partial") -> 1 | E22: =COUNTIFS('Follow-up questions'!$B$4:$B$68,$A22,'Follow-up questions'!$K$4:$K$68,"Gap") -> 0 | F22: =COUNTIFS('Follow-up questions'!$B$4:$B$68,$A22,'Follow-up questions'!$K$4:$K$68,"Not assessed") -> 1
A23: Total | B23: =SUM(B5:B22) -> 65 | C23: =SUM(C5:C22) -> 30 | D23: =SUM(D5:D22) -> 26 | E23: =SUM(E5:E22) -> 7 | F23: =SUM(F5:F22) -> 2
A26: Vendor reply to the 65 new questions
A27: Full | B27: =COUNTIF('Follow-up questions'!$J$4:$J$68,"Full") -> 51
A28: Partial | B28: =COUNTIF('Follow-up questions'!$J$4:$J$68,"Partial") -> 11
A29: Declined | B29: =COUNTIF('Follow-up questions'!$J$4:$J$68,"Declined") -> 1
A30: No reply | B30: =COUNTIF('Follow-up questions'!$J$4:$J$68,"No reply") -> 2
A33: Initial findings: outcome (22)
A34: Closed | B34: =COUNTIF(Findings!$E$5:$E$26,"Closed") -> 8
A35: Closed for go-live scope | B35: =COUNTIF(Findings!$E$5:$E$26,"Closed for go-live scope") -> 2
A36: Risk accepted (signed) | B36: =COUNTIF(Findings!$E$5:$E$26,"Risk accepted (signed)") -> 1
A37: Partly closed | B37: =COUNTIF(Findings!$E$5:$E$26,"Partly closed") -> 6
A38: Open | B38: =COUNTIF(Findings!$E$5:$E$26,"Open") -> 3
A39: Open (agreed, unsigned) | B39: =COUNTIF(Findings!$E$5:$E$26,"Open (agreed, unsigned)") -> 2
A40: Total | B40: =SUM(B34:B39) -> 22
A43: Open findings by severity
B44: Initial | C44: After follow-up
A45: High | B45: 5 | C45: =COUNTIF(Findings!$F$5:$F$37,"High") -> 2
A46: Medium | B46: 16 | C46: =COUNTIF(Findings!$F$5:$F$37,"Medium") -> 13
A47: Low | B47: 1 | C47: =COUNTIF(Findings!$F$5:$F$37,"Low") -> 7
A48: Total | B48: =SUM(B45:B47) -> 22 | C48: =SUM(C45:C47) -> 22
A49: New findings in the follow-up | C49: =COUNTIF(Findings!$C$5:$C$37,"New") -> 11
A52: Go-live conditions (10)
A53: Verified | B53: =COUNTIF(Conditions!$C$4:$C$13,"Verified") -> 2
A54: Verified with residual | B54: =COUNTIF(Conditions!$C$4:$C$13,"Verified with residual") -> 2
...

Sheet Findings
A1: Findings after the follow-up
A2: Severity after the follow-up is the verified severity: Closed means closed, avoided or accepted with sign-off. For new findings, the severity is the original rating.
A4: Finding | B4: Title | C4: Origin | D4: Severity initial | E4: Follow-up outcome | F4: Severity after the follow-up | G4: Evidence | H4: What the vendor said or what we found | I4: Next step
A5: FND-01 | B5: Wide standing access to connector credentials | C5: Initial | D5: High | E5: Closed | F5: Closed | G5: EV-28, EV-26 | H5: Read access limited to 3 platform security roles. Break-glass needs two-person approval. | I5: None
A6: FND-02 | B6: Connector credentials rotated only once a year | C6: Initial | D6: High | E6: Partly closed | F6: Medium | G6: EV-29, EV-30 | H6: 90-day automated rotation. Revocation within 4 hours by the support desk. No self-service. | I6: Reassess after the second rotation (Feb 2027). The bank can disable its own HR account at once
A7: FND-03 | B7: Standing support access from India with no transfer assessment | C7: Initial | D7: High | E7: Partly closed | F7: Medium | G7: EV-26, EV-27, EV-31 | H7: Just-in-time access live since 9 Nov. Transfer assessment for India provided. Masking for offshore staff by 30 Apr 2027. | I7: Masking by 30 Apr 2027. DPO accepts the assessment with that condition
A8: FND-04 | B8: Undisclosed AI model provider with US hosting | C8: Initial | D8: High | E8: Closed for go-live scope | F8: Closed | G8: EV-32, EV-33 | H8: Provider named (Model Provider Z, US). Assistant disabled for the bank on 12 Nov. Full contract withheld. | I8: Reopen before the assistant is ever enabled
A9: FND-05 | B9: Audit and inspection rights too limited | C9: Initial | D9: High | E9: Open | F9: High | G9: EV-34 | H9: Counter: two on-site audits a year with 10 working days' notice, unrestricted for regulators, pooled audits. | I9: Not accepted by Legal. Escalated to the risk committee
A10: FND-06 | B10: Vendor's own PCI DSS attestation missing | C10: Initial | D10: Medium | E10: Closed | F10: Closed | G10: EV-35, EV-04 | H10: A qualified assessor letter says the vendor is out of scope (tokens only). Card Provider Y attestation valid. | I10: Virtual cards can be enabled
A11: FND-07 | B11: No four-eyes control on the allowance rate table | C11: Initial | D11: Medium | E11: Open | F11: Medium | G11: none | H11: Planned for Q2 2027. Interim: a weekly change-log extract to Finance. | I11: Finance reviews the log weekly (BA-05) until the feature ships
A12: FND-08 | B12: Assurance reports are outdated or narrow | C12: Initial | D12: Medium | E12: Partly closed | F12: Low | G12: EV-36 | H12: Bridge letter issued. Scope extension to visa, gifts and card modules in the 2027 audit. | I12: Scope extension by 31 Dec 2027
A13: FND-09 | B13: No mutual TLS on bank-facing connections | C13: Initial | D13: Medium | E13: Risk accepted (signed) | F13: Closed | G13: EV-37 | H13: No mutual TLS. Private-key JWT, IP allow-list and 15-minute tokens. | I13: Bank IT security signed the acceptance
A14: FND-10 | B14: Recovery targets not proven | C14: Initial | D14: Medium | E14: Closed | F14: Closed | G14: EV-38 | H14: Test on 18 Nov: 3 hours 40 minutes against 4 hours. | I14: Repeat yearly
A15: FND-11 | B15: Guest data kept 24 months without deletion | C15: Initial | D15: Medium | E15: Closed | F15: Closed | G15: EV-39 | H15: 90-day automatic deletion live from 20 Nov. | I15: None
... A37: FND-33 | B37: No public vulnerability disclosure programme | C37: New | D37: Low | E37: New (open) | F37: Low | G37: OS-10 | H37: No programme and no security.txt page. Planned for 2027. | I37: Publish a security contact page and start a disclosure programme.

Sheet Risk register
A1: Risk register with four scores
A2: L = likelihood, I = impact (1 to 5). Bands: 1 to 4 Low, 5 to 9 Medium, 10 to 15 High, 16 to 25 Very high. New risks were not identified in the initial assessment.
D4: Inherent | H4: Initial current | L4: Verified after the follow-up | P4: Target
A5: Risk | B5: Risk description | C5: Findings | D5: L | E5: I | F5: Score | G5: Band | H5: L | I5: I | J5: Score | K5: Band | L5: L | M5: I | N5: Score | O5: Band | P5: L | Q5: I | R5: Score | S5: Band | T5: Movement | U5: Treatment | V5: Owner
A6: RR-01 | B6: Stolen connector credential allows bulk reading of employee data | C6: FND-01, FND-02, FND-09 | D6: 4 | E6: 5 | F6: =IF(D6="","",D6*E6) -> 20 | G6: =IF(F6="","",IF(F6>=16,"Very high",IF(F6>=10,"High",IF(F6>=5,"Medium","Low")))) -> Very high | H6: 3 | I6: 5 | J6: =IF(H6="","",H6*I6) -> 15 | K6: =IF(J6="","",IF(J6>=16,"Very high",IF(J6>=10,"High",IF(J6>=5,"Medium","Low")))) -> High | L6: 2 | M6: 4 | N6: =IF(L6="","",L6*M6) -> 8 | O6: =IF(N6="","",IF(N6>=16,"Very high",IF(N6>=10,"High",IF(N6>=5,"Medium","Low")))) -> Medium | P6: 2 | Q6: 4 | R6: =IF(P6="","",P6*Q6) -> 8 | S6: =IF(R6="","",IF(R6>=16,"Very high",IF(R6>=10,"High",IF(R6>=5,"Medium","Low")))) -> Medium | T6: =IF(J6="","New",IF(N6<J6,"Down",IF(N6>J6,"Up","Same"))) -> Down | U6: Mitigate | V6: Bank IT security
A7: RR-02 | B7: Standing support access from India exposes production data | C7: FND-03, FND-30 | D7: 4 | E7: 4 | F7: =IF(D7="","",D7*E7) -> 16 | G7: =IF(F7="","",IF(F7>=16,"Very high",IF(F7>=10,"High",IF(F7>=5,"Medium","Low")))) -> Very high | H7: 4 | I7: 4 | J7: =IF(H7="","",H7*I7) -> 16 | K7: =IF(J7="","",IF(J7>=16,"Very high",IF(J7>=10,"High",IF(J7>=5,"Medium","Low")))) -> Very high | L7: 3 | M7: 4 | N7: =IF(L7="","",L7*M7) -> 12 | O7: =IF(N7="","",IF(N7>=16,"Very high",IF(N7>=10,"High",IF(N7>=5,"Medium","Low")))) -> High | P7: 2 | Q7: 4 | R7: =IF(P7="","",P7*Q7) -> 8 | S7: =IF(R7="","",IF(R7>=16,"Very high",IF(R7>=10,"High",IF(R7>=5,"Medium","Low")))) -> Medium | T7: =IF(J7="","New",IF(N7<J7,"Down",IF(N7>J7,"Up","Same"))) -> Down | U7: Mitigate | V7: Bank DPO and TPRM
A8: RR-03 | B8: Personal data reaches an undisclosed AI provider in the US | C8: FND-04 | D8: 3 | E8: 4 | F8: =IF(D8="","",D8*E8) -> 12 | G8: =IF(F8="","",IF(F8>=16,"Very high",IF(F8>=10,"High",IF(F8>=5,"Medium","Low")))) -> High | H8: 4 | I8: 4 | J8: =IF(H8="","",H8*I8) -> 16 | K8: =IF(J8="","",IF(J8>=16,"Very high",IF(J8>=10,"High",IF(J8>=5,"Medium","Low")))) -> Very high | L8: 1 | M8: 4 | N8: =IF(L8="","",L8*M8) -> 4 | O8: =IF(N8="","",IF(N8>=16,"Very high",IF(N8>=10,"High",IF(N8>=5,"Medium","Low")))) -> Low | P8: 1 | Q8: 4 | R8: =IF(P8="","",P8*Q8) -> 4 | S8: =IF(R8="","",IF(R8>=16,"Very high",IF(R8>=10,"High",IF(R8>=5,"Medium","Low")))) -> Low | T8: =IF(J8="","New",IF(N8<J8,"Down",IF(N8>J8,"Up","Same"))) -> Down | U8: Avoided (feature off) | V8: Bank TPRM
A9: RR-04 | B9: Fraudulent or altered invoice reaches the ERP | C9: FND-21 | D9: 3 | E9: 4 | F9: =IF(D9="","",D9*E9) -> 12 | G9: =IF(F9="","",IF(F9>=16,"Very high",IF(F9>=10,"High",IF(F9>=5,"Medium","Low")))) -> High | H9: 3 | I9: 3 | J9: =IF(H9="","",H9*I9) -> 9 | K9: =IF(J9="","",IF(J9>=16,"Very high",IF(J9>=10,"High",IF(J9>=5,"Medium","Low")))) -> Medium | L9: 2 | M9: 3 | N9: =IF(L9="","",L9*M9) -> 6 | O9: =IF(N9="","",IF(N9>=16,"Very high",IF(N9>=10,"High",IF(N9>=5,"Medium","Low")))) -> Medium | P9: 2 | Q9: 3 | R9: =IF(P9="","",P9*Q9) -> 6 | S9: =IF(R9="","",IF(R9>=16,"Very high",IF(R9>=10,"High",IF(R9>=5,"Medium","Low")))) -> Medium | T9: =IF(J9="","New",IF(N9<J9,"Down",IF(N9>J9,"Up","Same"))) -> Down | U9: Mitigate | V9: Bank Finance
A10: RR-05 | B10: Fraudulent allowance payments through rate-table changes | C10: FND-07 | D10: 3 | E10: 3 | F10: =IF(D10="","",D10*E10) -> 9 | G10: =IF(F10="","",IF(F10>=16,"Very high",IF(F10>=10,"High",IF(F10>=5,"Medium","Low")))) -> Medium | H10: 3 | I10: 3 | J10: =IF(H10="","",H10*I10) -> 9 | K10: =IF(J10="","",IF(J10>=16,"Very high",IF(J10>=10,"High",IF(J10>=5,"Medium","Low")))) -> Medium | L10: 2 | M10: 3 | N10: =IF(L10="","",L10*M10) -> 6 | O10: =IF(N10="","",IF(N10>=16,"Very high",IF(N10>=10,"High",IF(N10>=5,"Medium","Low")))) -> Medium | P10: 1 | Q10: 3 | R10: =IF(P10="","",P10*Q10) -> 3 | S10: =IF(R10="","",IF(R10>=16,"Very high",IF(R10>=10,"High",IF(R10>=5,"Medium","Low")))) -> Low | T10: =IF(J10="","New",IF(N10<J10,"Down",IF(N10>J10,"Up","Same"))) -> Down | U10: Mitigate (interim review) | V10: Bank Finance
A11: RR-06 | B11: Card misuse or PCI non-compliance | C11: FND-06 | D11: 3 | E11: 4 | F11: =IF(D11="","",D11*E11) -> 12 | G11: =IF(F11="","",IF(F11>=16,"Very high",IF(F11>=10,"High",IF(F11>=5,"Medium","Low")))) -> High | H11: 2 | I11: 4 | J11: =IF(H11="","",H11*I11) -> 8 | K11: =IF(J11="","",IF(J11>=16,"Very high",IF(J11>=10,"High",IF(J11>=5,"Medium","Low")))) -> Medium | L11: 1 | M11: 4 | N11: =IF(L11="","",L11*M11) -> 4 | O11: =IF(N11="","",IF(N11>=16,"Very high",IF(N11>=10,"High",IF(N11>=5,"Medium","Low")))) -> Low | P11: 1 | Q11: 4 | R11: =IF(P11="","",P11*Q11) -> 4 | S11: =IF(R11="","",IF(R11>=16,"Very high",IF(R11>=10,"High",IF(R11>=5,"Medium","Low")))) -> Low | T11: =IF(J11="","New",IF(N11<J11,"Down",IF(N11>J11,"Up","Same"))) -> Down | U11: Mitigated | V11: Bank Finance and TPRM
A12: RR-07 | B12: Outage or slow recovery of the platform | C12: FND-10, FND-31 | D12: 3 | E12: 3 | F12: =IF(D12="","",D12*E12) -> 9 | G12: =IF(F12="","",IF(F12>=16,"Very high",IF(F12>=10,"High",IF(F12>=5,"Medium","Low")))) -> Medium | H12: 3 | I12: 3 | J12: =IF(H12="","",H12*I12) -> 9 | K12: =IF(J12="","",IF(J12>=16,"Very high",IF(J12>=10,"High",IF(J12>=5,"Medium","Low")))) -> Medium | L12: 3 | M12: 3 | N12: =IF(L12="","",L12*M12) -> 9 | O12: =IF(N12="","",IF(N12>=16,"Very high",IF(N12>=10,"High",IF(N12>=5,"Medium","Low")))) -> Medium | P12: 2 | Q12: 3 | R12: =IF(P12="","",P12*Q12) -> 6 | S12: =IF(R12="","",IF(R12>=16,"Very high",IF(R12>=10,"High",IF(R12>=5,"Medium","Low")))) -> Medium | T12: =IF(J12="","New",IF(N12<J12,"Down",IF(N12>J12,"Up","Same"))) -> Same | U12: Mitigate | V12: Bank TPRM
A13: RR-08 | B13: Late breach notice, costly incident assistance and a low liability cap | C13: FND-16, FND-29, FND-32 | D13: 3 | E13: 4 | F13: =IF(D13="","",D13*E13) -> 12 | G13: =IF(F13="","",IF(F13>=16,"Very high",IF(F13>=10,"High",IF(F13>=5,"Medium","Low")))) -> High | H13: 3 | I13: 4 | J13: =IF(H13="","",H13*I13) -> 12 | K13: =IF(J13="","",IF(J13>=16,"Very high",IF(J13>=10,"High",IF(J13>=5,"Medium","Low")))) -> High | L13: 3 | M13: 4 | N13: =IF(L13="","",L13*M13) -> 12 | O13: =IF(N13="","",IF(N13>=16,"Very high",IF(N13>=10,"High",IF(N13>=5,"Medium","Low")))) -> High | P13: 2 | Q13: 3 | R13: =IF(P13="","",P13*Q13) -> 6 | S13: =IF(R13="","",IF(R13>=16,"Very high",IF(R13>=10,"High",IF(R13>=5,"Medium","Low")))) -> Medium | T13: =IF(J13="","New",IF(N13<J13,"Down",IF(N13>J13,"Up","Same"))) -> Same | U13: Transfer (contract) and mitigate | V13: Bank Legal
A14: RR-09 | B14: Excess retention and exposure of guest, log and test data | C14: FND-11, FND-13, FND-14 | D14: 4 | E14: 3 | F14: =IF(D14="","",D14*E14) -> 12 | G14: =IF(F14="","",IF(F14>=16,"Very high",IF(F14>=10,"High",IF(F14>=5,"Medium","Low")))) -> High | H14: 3 | I14: 3 | J14: =IF(H14="","",H14*I14) -> 9 | K14: =IF(J14="","",IF(J14>=16,"Very high",IF(J14>=10,"High",IF(J14>=5,"Medium","Low")))) -> Medium | L14: 2 | M14: 3 | N14: =IF(L14="","",L14*M14) -> 6 | O14: =IF(N14="","",IF(N14>=16,"Very high",IF(N14>=10,"High",IF(N14>=5,"Medium","Low")))) -> Medium | P14: 2 | Q14: 2 | R14: =IF(P14="","",P14*Q14) -> 4 | S14: =IF(R14="","",IF(R14>=16,"Very high",IF(R14>=10,"High",IF(R14>=5,"Medium","Low")))) -> Low | T14: =IF(J14="","New",IF(N14<J14,"Down",IF(N14>J14,"Up","Same"))) -> Down | U14: Mitigate | V14: Bank DPO
A15: RR-10 | B15: Unseen fourth parties and late notice of change | C15: FND-12 | D15: 4 | E15: 3 | F15: =IF(D15="","",D15*E15) -> 12 | G15: =IF(F15="","",IF(F15>=16,"Very high",IF(F15>=10,"High",IF(F15>=5,"Medium","Low")))) -> High | H15: 3 | I15: 3 | J15: =IF(H15="","",H15*I15) -> 9 | K15: =IF(J15="","",IF(J15>=16,"Very high",IF(J15>=10,"High",IF(J15>=5,"Medium","Low")))) -> Medium | L15: 3 | M15: 3 | N15: =IF(L15="","",L15*M15) -> 9 | O15: =IF(N15="","",IF(N15>=16,"Very high",IF(N15>=10,"High",IF(N15>=5,"Medium","Low")))) -> Medium | P15: 3 | Q15: 2 | R15: =IF(P15="","",P15*Q15) -> 6 | S15: =IF(R15="","",IF(R15>=16,"Very high",IF(R15>=10,"High",IF(R15>=5,"Medium","Low")))) -> Medium | T15: =IF(J15="","New",IF(N15<J15,"Down",IF(N15>J15,"Up","Same"))) -> Same | U15: Mitigate | V15: Bank TPRM
A16: RR-11 | B16: No effective audit or exit rights for a critical service | C16: FND-05, FND-15 | D16: 3 | E16: 5 | F16: =IF(D16="","",D16*E16) -> 15 | G16: =IF(F16="","",IF(F16>=16,"Very high",IF(F16>=10,"High",IF(F16>=5,"Medium","Low")))) -> High | H16: 3 | I16: 5 | J16: =IF(H16="","",H16*I16) -> 15 | K16: =IF(J16="","",IF(J16>=16,"Very high",IF(J16>=10,"High",IF(J16>=5,"Medium","Low")))) -> High | L16: 3 | M16: 5 | N16: =IF(L16="","",L16*M16) -> 15 | O16: =IF(N16="","",IF(N16>=16,"Very high",IF(N16>=10,"High",IF(N16>=5,"Medium","Low")))) -> High | P16: 1 | Q16: 5 | R16: =IF(P16="","",P16*Q16) -> 5 | S16: =IF(R16="","",IF(R16>=16,"Very high",IF(R16>=10,"High",IF(R16>=5,"Medium","Low")))) -> Medium | T16: =IF(J16="","New",IF(N16<J16,"Down",IF(N16>J16,"Up","Same"))) -> Same | U16: Transfer (contract) and mitigate | V16: Bank Legal and Procurement
A17: RR-12 | B17: Reliance on outdated or narrow assurance reports | C17: FND-08, FND-28 | D17: 3 | E17: 3 | F17: =IF(D17="","",D17*E17) -> 9 | G17: =IF(F17="","",IF(F17>=16,"Very high",IF(F17>=10,"High",IF(F17>=5,"Medium","Low")))) -> Medium | H17: 3 | I17: 3 | J17: =IF(H17="","",H17*I17) -> 9 | K17: =IF(J17="","",IF(J17>=16,"Very high",IF(J17>=10,"High",IF(J17>=5,"Medium","Low")))) -> Medium | L17: 3 | M17: 3 | N17: =IF(L17="","",L17*M17) -> 9 | O17: =IF(N17="","",IF(N17>=16,"Very high",IF(N17>=10,"High",IF(N17>=5,"Medium","Low")))) -> Medium | P17: 2 | Q17: 3 | R17: =IF(P17="","",P17*Q17) -> 6 | S17: =IF(R17="","",IF(R17>=16,"Very high",IF(R17>=10,"High",IF(R17>=5,"Medium","Low")))) -> Medium | T17: =IF(J17="","New",IF(N17<J17,"Down",IF(N17>J17,"Up","Same"))) -> Same | U17: Mitigate | V17: Bank TPRM
... A22: RR-17 | B22: Minor misuse of loyalty data, discount codes or booker accounts | C22: FND-22 | D22: 3 | E22: 2 | F22: =IF(D22="","",D22*E22) -> 6 | G22: =IF(F22="","",IF(F22>=16,"Very high",IF(F22>=10,"High",IF(F22>=5,"Medium","Low")))) -> Medium | H22: 3 | I22: 2 | J22: =IF(H22="","",H22*I22) -> 6 | K22: =IF(J22="","",IF(J22>=16,"Very high",IF(J22>=10,"High",IF(J22>=5,"Medium","Low")))) -> Medium | L22: 3 | M22: 2 | N22: =IF(L22="","",L22*M22) -> 6 | O22: =IF(N22="","",IF(N22>=16,"Very high",IF(N22>=10,"High",IF(N22>=5,"Medium","Low")))) -> Medium | P22: 2 | Q22: 2 | R22: =IF(P22="","",P22*Q22) -> 4 | S22: =IF(R22="","",IF(R22>=16,"Very high",IF(R22>=10,"High",IF(R22>=5,"Medium","Low")))) -> Low | T22: =IF(J22="","New",IF(N22<J22,"Down",IF(N22>J22,"Up","Same"))) -> Same | U22: Accept | V22: Bank HR
A23: RR-18 | B23: Personal data stored outside the EU through US backup replication | C23: FND-23 | D23: 3 | E23: 4 | F23: =IF(D23="","",D23*E23) -> 12 | G23: =IF(F23="","",IF(F23>=16,"Very high",IF(F23>=10,"High",IF(F23>=5,"Medium","Low")))) -> High | J23: =IF(H23="","",H23*I23) | K23: =IF(J23="","",IF(J23>=16,"Very high",IF(J23>=10,"High",IF(J23>=5,"Medium","Low")))) | L23: 4 | M23: 4 | N23: =IF(L23="","",L23*M23) -> 16 | O23: =IF(N23="","",IF(N23>=16,"Very high",IF(N23>=10,"High",IF(N23>=5,"Medium","Low")))) -> Very high | P23: 1 | Q23: 4 | R23: =IF(P23="","",P23*Q23) -> 4 | S23: =IF(R23="","",IF(R23>=16,"Very high",IF(R23>=10,"High",IF(R23>=5,"Medium","Low")))) -> Low | T23: =IF(J23="","New",IF(N23<J23,"Down",IF(N23>J23,"Up","Same"))) -> New | U23: Mitigate (new, High) | V23: Bank DPO
A24: RR-19 | B24: Application vulnerability reaches production through weak development controls | C24: FND-24, FND-25, FND-26, FND-33 | D24: 3 | E24: 4 | F24: =IF(D24="","",D24*E24) -> 12 | G24: =IF(F24="","",IF(F24>=16,"Very high",IF(F24>=10,"High",IF(F24>=5,"Medium","Low")))) -> High | J24: =IF(H24="","",H24*I24) | K24: =IF(J24="","",IF(J24>=16,"Very high",IF(J24>=10,"High",IF(J24>=5,"Medium","Low")))) | L24: 3 | M24: 3 | N24: =IF(L24="","",L24*M24) -> 9 | O24: =IF(N24="","",IF(N24>=16,"Very high",IF(N24>=10,"High",IF(N24>=5,"Medium","Low")))) -> Medium | P24: 2 | Q24: 3 | R24: =IF(P24="","",P24*Q24) -> 6 | S24: =IF(R24="","",IF(R24>=16,"Very high",IF(R24>=10,"High",IF(R24>=5,"Medium","Low")))) -> Medium | T24: =IF(J24="","New",IF(N24<J24,"Down",IF(N24>J24,"Up","Same"))) -> New | U24: Mitigate (new) | V24: Bank IT security
A25: RR-20 | B25: Encryption keys weakly protected | C25: FND-27 | D25: 2 | E25: 4 | F25: =IF(D25="","",D25*E25) -> 8 | G25: =IF(F25="","",IF(F25>=16,"Very high",IF(F25>=10,"High",IF(F25>=5,"Medium","Low")))) -> Medium | J25: =IF(H25="","",H25*I25) | K25: =IF(J25="","",IF(J25>=16,"Very high",IF(J25>=10,"High",IF(J25>=5,"Medium","Low")))) | L25: 2 | M25: 4 | N25: =IF(L25="","",L25*M25) -> 8 | O25: =IF(N25="","",IF(N25>=16,"Very high",IF(N25>=10,"High",IF(N25>=5,"Medium","Low")))) -> Medium | P25: 1 | Q25: 4 | R25: =IF(P25="","",P25*Q25) -> 4 | S25: =IF(R25="","",IF(R25>=16,"Very high",IF(R25>=10,"High",IF(R25>=5,"Medium","Low")))) -> Low | T25: =IF(J25="","New",IF(N25<J25,"Down",IF(N25>J25,"Up","Same"))) -> New | U25: Mitigate (new) | V25: Bank IT security
A26: RR-21 | B26: Misuse or data leakage by offshore support staff | C26: FND-30 | D26: 3 | E26: 4 | F26: =IF(D26="","",D26*E26) -> 12 | G26: =IF(F26="","",IF(F26>=16,"Very high",IF(F26>=10,"High",IF(F26>=5,"Medium","Low")))) -> High | J26: =IF(H26="","",H26*I26) | K26: =IF(J26="","",IF(J26>=16,"Very high",IF(J26>=10,"High",IF(J26>=5,"Medium","Low")))) | L26: 3 | M26: 3 | N26: =IF(L26="","",L26*M26) -> 9 | O26: =IF(N26="","",IF(N26>=16,"Very high",IF(N26>=10,"High",IF(N26>=5,"Medium","Low")))) -> Medium | P26: 2 | Q26: 3 | R26: =IF(P26="","",P26*Q26) -> 6 | S26: =IF(R26="","",IF(R26>=16,"Very high",IF(R26>=10,"High",IF(R26>=5,"Medium","Low")))) -> Medium | T26: =IF(J26="","New",IF(N26<J26,"Down",IF(N26>J26,"Up","Same"))) -> New | U26: Mitigate (new) | V26: Bank DPO and TPRM
B28: Risks by band (all rows)
B29: Band | G29: Inherent | K29: Initial | O29: Follow-up | S29: Target
B30: Very high | G30: =COUNTIF(G6:G26,"Very high") -> 2 | K30: =COUNTIF(K6:K26,"Very high") -> 2 | O30: =COUNTIF(O6:O26,"Very high") -> 1 | S30: =COUNTIF(S6:S26,"Very high") -> 0
B31: High | G31: =COUNTIF(G6:G26,"High") -> 12 | K31: =COUNTIF(K6:K26,"High") -> 4 | O31: =COUNTIF(O6:O26,"High") -> 3 | S31: =COUNTIF(S6:S26,"High") -> 0
B32: Medium | G32: =COUNTIF(G6:G26,"Medium") -> 7 | K32: =COUNTIF(K6:K26,"Medium") -> 11 | O32: =COUNTIF(O6:O26,"Medium") -> 13 | S32: =COUNTIF(S6:S26,"Medium") -> 12
B33: Low | G33: =COUNTIF(G6:G26,"Low") -> 0 | K33: =COUNTIF(K6:K26,"Low") -> 0 | O33: =COUNTIF(O6:O26,"Low") -> 4 | S33: =COUNTIF(S6:S26,"Low") -> 9
B36: Existing 17 risks only (same population in the initial assessment and the follow-up)
B37: Very high | G37: =COUNTIF(G6:G22,"Very high") -> 2 | K37: =COUNTIF(K6:K22,"Very high") -> 2 | O37: =COUNTIF(O6:O22,"Very high") -> 0 | S37: =COUNTIF(S6:S22,"Very high") -> 0
B38: High | G38: =COUNTIF(G6:G22,"High") -> 9 | K38: =COUNTIF(K6:K22,"High") -> 4 | O38: =COUNTIF(O6:O22,"High") -> 3 | S38: =COUNTIF(S6:S22,"High") -> 0
B39: Medium | G39: =COUNTIF(G6:G22,"Medium") -> 6 | K39: =COUNTIF(K6:K22,"Medium") -> 11 | O39: =COUNTIF(O6:O22,"Medium") -> 10 | S39: =COUNTIF(S6:S22,"Medium") -> 10
B40: Low | G40: =COUNTIF(G6:G22,"Low") -> 0 | K40: =COUNTIF(K6:K22,"Low") -> 0 | O40: =COUNTIF(O6:O22,"Low") -> 4 | S40: =COUNTIF(S6:S22,"Low") -> 7

Sheet Conditions
A1: Go-live conditions after the follow-up
A3: Action | B3: Condition (due before go-live) | C3: Status | D3: Evidence | E3: Residual or next step | F3: Owner | G3: Due
A4: REM-01 | B4: Secret read access limited to named roles, with approval and logging | C4: Verified | D4: EV-28, EV-26 | E4: None | F4: Vendor X | G4: 15 Jan 2027
A5: REM-02 | B5: Credentials rotate at least every 90 days and the bank can revoke them | C5: Verified with residual | D5: EV-29, EV-30 | E5: No self-service revoke. Vendor revokes in 4 hours. Reassess Feb 2027 | F5: Vendor X | G5: 15 Jan 2027
A6: REM-03 | B6: Just-in-time production access, masked data offshore, transfer assessment | C6: Verified with residual | D6: EV-26, EV-27, EV-31 | E6: Masking by 30 Apr 2027 | F6: Vendor X and Bank DPO | G6: 15 Jan 2027
A7: REM-05 | B7: Unrestricted audit, access and inspection rights in the contract | C7: Not met | D7: EV-34 | E7: Vendor counter is not unrestricted. Risk committee decision | F7: Bank Legal | G7: 15 Jan 2027
A8: REM-08 | B8: SOC 2 bridge letter | C8: Verified | D8: EV-36 | E8: Scope extension by 31 Dec 2027 | F8: Vendor X | G8: 15 Jan 2027
A9: REM-12 | B9: Notice and a right to object for every subprocessor change | C9: In progress | D9: EV-45 | E9: Agreed in the redline, not signed | F9: Bank Legal | G9: 15 Jan 2027
A10: REM-15 | B10: Insolvency and data-return clause, credentials revoked within 24 hours of the end | C10: In progress | D10: EV-45 | E10: Agreed in the redline, not signed. Exit test by 30 Jun 2027 | F10: Bank Legal | G10: 15 Jan 2027
A11: REM-16 | B11: Incident notice within 24 hours and an assistance rate card | C11: Partly met | D11: EV-46 | E11: 48 hours offered. Legal decides | F11: Bank Legal | G11: 15 Jan 2027
A12: REM-23 | B12: No data stored outside the EU (new High) | C12: Not met | D12: EV-47 | E12: Vendor committed to delete by 15 Dec 2026. Evidence pending | F12: Vendor X | G12: 15 Jan 2027
A13: REM-32 | B13: Liability cap aligned with the potential loss (new) | C13: In progress | D13: EV-61 | E13: Negotiating a higher cap for data breach | F13: Bank Legal | G13: 15 Jan 2027
A15: Feature gates
A16: Action | B16: Feature | C16: Status | D16: Evidence | E16: Note
A17: REM-04 | B17: AI assistant stays off for the bank | C17: Verified (feature off) | D17: EV-32 | E17: Reopen FND-04 before any enabling
A18: REM-06 | B18: Virtual cards | C18: Verified (can be enabled) | D18: EV-35, EV-04 | E18: Qualified assessor letter accepted

Sheet New actions
A1: New remediation actions from the follow-up
A3: Action | B3: Finding | C3: Severity | D3: Action | E3: Owner | F3: Due | G3: Type | H3: Evidence to verify | I3: Status
A4: REM-23 | B4: FND-23 | C4: High | D4: Stop replication to the US archive, delete existing US copies and provide a deletion certificate. The vendor's own target is 15 Dec 2026. | E4: Vendor X, verified by Bank DPO | F4: 15 Jan 2027 | G4: Pre-go-live | H4: Deletion certificate and a new region diagram | I4: Open
A5: REM-24 | B5: FND-24 | C5: Medium | D5: Fix High scan findings within 14 days, run dynamic testing monthly and report ageing. | E5: Vendor X | F5: 30 Apr 2027 | G5: Within 90 days | H5: Scan summaries | I5: Open
A6: REM-25 | B6: FND-25 | C6: Medium | D6: Enforce branch protection for administrators and add a second reviewer for infrastructure code. | E6: Vendor X | F6: 30 Apr 2027 | G6: Within 90 days | H6: Rule screenshots | I6: Open
A7: REM-26 | B7: FND-26 | C7: Low | D7: Provide the software bill of materials when available. | E7: Vendor X | F7: 30 Jun 2027 | G7: Track | H7: Bill of materials | I7: Open
A8: REM-27 | B8: FND-27 | C8: Medium | D8: Separate key custodians, rotate keys at least yearly and offer customer-managed keys. | E8: Vendor X | F8: 30 Apr 2027 | G8: Within 90 days | H8: Key policy and rotation log | I8: Open
A9: REM-28 | B9: FND-28 | C9: Medium | D9: Assign the 14 customer controls to bank owners and follow up the SOC 2 exceptions. | E9: Bank TPRM and Vendor X | F9: 30 Apr 2027 | G9: Within 90 days | H9: Control ownership list | I9: Open
A10: REM-29 | B10: FND-29 | C10: Low | D10: Run a joint incident exercise and share root cause summaries. | E10: Vendor X and Bank TPRM | F10: 30 Jun 2027 | G10: Track | H10: Exercise report | I10: Open
A11: REM-30 | B11: FND-30 | C11: Medium | D11: Align offshore screening where lawful, enable endpoint protection and block USB storage on support laptops. | E11: Vendor X | F11: 30 Apr 2027 | G11: Within 90 days | H11: Policy and endpoint report | I11: Open
A12: REM-31 | B12: FND-31 | C12: Medium | D12: Run a restore test and move backups to a separate account. | E12: Vendor X | F12: 30 Apr 2027 | G12: Within 90 days | H12: Restore test record | I12: Open
A13: REM-32 | B13: FND-32 | C13: Medium | D13: Agree a separate higher cap for data breach and confidentiality in the contract. | E13: Bank Legal | F13: 15 Jan 2027 | G13: Pre-go-live | H13: Signed contract clause | I13: Open
A14: REM-33 | B14: FND-33 | C14: Low | D14: Publish a security contact page and start a disclosure programme. | E14: Vendor X | F14: 31 Jul 2027 | G14: Track | H14: Public page | I14: Open

Sheet Follow-up questions
A1: Follow-up questions and vendor replies (simulated)
A3: ID | B3: Area | C3: Question | D3: Priority | E3: Asked by | F3: Linked to | G3: Control | H3: Evidence to request | I3: Vendor reply (simulated) | J3: Reply | K3: Rating | L3: Assessor notes
A4: FU-IAM-01 | B4: Identity and access management | C4: How is privileged access to production systems granted (just-in-time, approval, expiry), and how long can a privileged session last? | D4: Must | E4: IT security | F4: FND-03 | G4: CR-09 | H4: Privileged access tool configuration; 30-day access log | I4: All production access goes through a privileged access tool. Requests need team-lead approval, expire after 4 hours and are recorded. Standing access was removed on 9 Nov 2026. | J4: Full | K4: Satisfactory | L4: EV-26, EV-27. 30-day log shows no standing sessions. Closes part of FND-03.
A5: FU-IAM-02 | B5: Identity and access management | C5: Provide the privileged account inventory and the date of the last privileged access review. | D5: Must | E5: Analyst | F5: FND-01 | G5: CR-09 | H5: Account inventory; review record | I5: Inventory of 41 privileged accounts. Last review on 30 Sep 2026, three accounts removed. | J5: Full | K5: Satisfactory | L5: EV-26.
A6: FU-IAM-03 | B6: Identity and access management | C6: How are service accounts and API keys inventoried, owned and rotated? Which belong to the bank's connector? | D6: Must | E6: IT security | F6: FND-02 | G6: CR-04 | H6: Service-account inventory; rotation logs | I6: Inventory with owners provided. Connector keys now rotate every 90 days by an automated job. The first rotation ran on 14 Nov 2026. | J6: Full | K6: Satisfactory | L6: EV-29.
A7: FU-IAM-04 | B7: Identity and access management | C7: Can the bank revoke the connector's credentials itself, and how fast can the vendor revoke on request? | D7: Must | E7: IT security | F7: FND-02 | G7: CR-04 | H7: Revocation test record | I7: No self-service revoke. The 24/7 support desk revokes within 4 hours. Tested on 19 Nov: 2 hours 10 minutes. | J7: Partial | K7: Partial | L7: EV-30. The bank can disable its own HR service account at once, which is accepted as a compensating control.
A8: FU-IAM-05 | B8: Identity and access management | C8: How is segregation of duties enforced for vendor staff who can both deploy code and access production data? | D8: Should | E8: TPRM lead | F8: new | G8: CR-09 | H8: Segregation matrix; approved exceptions | I8: Matrix provided. Two on-call engineer roles overlap, with an approved exception and extra logging. | J8: Partial | K8: Partial | L8: EV-26. Exception approved by the vendor's security head. Sample reviewed.
A9: FU-DAT-01 | B9: Data security | C9: Provide the data classification scheme and show how passport data and executive itineraries are labelled and handled. | D9: Should | E9: DPO | F9: D2, D4 | G9: CR-12 | H9: Classification scheme; handling rules | I9: Four levels. Passport numbers are Restricted with field-level encryption. Executive itineraries are Confidential with restricted visibility. | J9: Full | K9: Satisfactory | L9: EV-66.
A10: FU-DAT-02 | B10: Data security | C10: Provide the record of where each data type is stored and processed, including every location of backups and replicas. | D10: Must | E10: DPO | F10: V6 | G10: CR-14 | H10: Data inventory; storage regions | I10: Inventory provided. Production runs in two EU regions. Cold-archive backups replicate to a US region for long-term retention. | J10: Full | K10: Gap | L10: EV-47. Contradicts the EU-only claim V6. New finding FND-23 (High).
A11: FU-DAT-03 | B11: Data security | C11: How are backups and snapshots encrypted, and who can restore them? | D11: Should | E11: IT security | F11: new | G11: CR-31 | H11: Backup encryption configuration; restore rights | I11: AES-256 with provider-managed keys. Restore limited to five named engineers, with approval. | J11: Full | K11: Partial | L11: EV-47. Key management weakness, see FND-27.
A12: FU-DAT-04 | B12: Data security | C12: How do you stop personal data leaving through endpoints and email (data loss prevention)? | D12: If applicable | E12: Analyst | F12: new | G12: CR-32 | H12: DLP configuration; device policies | I12: DLP covers corporate email and cloud storage. Offshore support laptops have no endpoint DLP, and USB storage is allowed at two of three support sites. | J12: Full | K12: Partial | L12: EV-64. See FND-30.
A13: FU-CRY-01 | B13: Cryptography and key management | C13: Who manages the encryption keys for databases and backups, and can the bank use its own keys? | D13: Must | E13: IT security | F13: FND-27 | G13: CR-31 | H13: Key management description | I13: Provider default keys in the cloud provider's key service. Customer-managed keys are not offered. | J13: Partial | K13: Partial | L13: EV-66. See FND-27.
A14: FU-CRY-02 | B14: Cryptography and key management | C14: How are key custodians separated, and how often are keys rotated and revoked? | D14: Must | E14: IT security | F14: FND-27 | G14: CR-31 | H14: Key policy; rotation log | I14: Key administration and key use sit with the same platform team. Rotation is yearly. | J14: Partial | K14: Gap | L14: EV-66. Fails the separation requirement. See FND-27.
... A68: FU-PHY-02 | B68: Physical security | C68: Describe physical access controls at your offices and the India support site. | D68: If applicable | E68: IT security | F68: new | G68: CR-32 | H68: Site description | I68: No reply. | J68: No reply | K68: Not assessed | L68: Not chased: if applicable and low priority.

Sheet Re-asked
A1: Questions left unassessed in the initial assessment, re-asked in the follow-up
A3: ID | B3: Domain | C3: Question | D3: Vendor reply (simulated) | E3: Reply | F3: Rating | G3: Assessor notes
A4: A1 | B4: Scope and service model | C4: Is the service multi-tenant SaaS, single-tenant cloud, or self-hosted? Which edition and version are we buying? | D4: Multi-tenant SaaS with a dedicated connector instance per client. The order form shows the enterprise edition. | E4: Full | F4: Satisfactory | G4: EV-66.
A5: A2 | B5: Scope and service model | C5: Which data categories will the service store or process (employee data, passport/ID numbers, financial data)? | D5: The data inventory covers D1 to D16. Prompt logs and US archive backups were missing until the follow-up. | E5: Full | F5: Partial | G5: EV-47. See FND-23.
A6: B4 | B6: Identity and sign-on | C6: What session timeout, re-authentication and device or network restrictions apply? | D6: Idle timeout 30 minutes, absolute 12 hours, re-authentication for payment settings. | E6: Full | F6: Satisfactory | G6: EV-66.
A7: C1 | B7: Provisioning and leavers | C7: How are accounts created (SCIM, API, manual, self-signup)? Is self-signup disabled? | D7: Accounts are created from the roster through the connector. Self-signup is disabled. | E7: Full | F7: Satisfactory | G7: EV-66.
A8: C3 | B8: Provisioning and leavers | C8: How are role changes (movers) reflected in groups, roles and entitlements? | D8: Role changes follow the HR record at the next nightly sync. | E8: Full | F8: Satisfactory | G8: EV-66.
A9: C4 | B9: Provisioning and leavers | C9: How are seats assigned and reclaimed, and are dormant accounts reported? | D9: Monthly seat report. 12 dormant accounts were flagged in Sep and removed. | E9: Full | F9: Satisfactory | G9: EV-66.
A10: E1 | B10: HR data sync | C10: Which employee fields are received, and are they limited to the minimum needed? | D10: The field mapping lists 14 fields. Gender and home address are not synced. | E10: Full | F10: Satisfactory | G10: EV-66.
A11: E2 | B11: HR data sync | C11: What method (REST, webhook, SFTP) and direction is used, and who initiates the connection? | D11: REST over HTTPS, opened by the connector. SFTP is not used for the roster. | E11: Full | F11: Satisfactory | G11: EV-66.
A12: F1 | B12: Approvals and policy | C12: How are policy rules defined, approved and version-controlled? | D12: Policy rules are versioned in the console with a change history. There is no second approval. | E12: Full | F12: Partial | G12: See FND-07.
A13: F2 | B13: Approvals and policy | C13: How is an approval request authenticated so it cannot be forged or replayed? | D13: Approval messages are signed, with a nonce and a 5-minute expiry. Covered by the penetration test. | E13: Full | F13: Satisfactory | G13: EV-59.
A14: F3 | B14: Approvals and policy | C14: Is segregation of duties enforced (a requester cannot approve their own booking)? | D14: A requester cannot approve their own trip. Test evidence provided. | E14: Full | F14: Satisfactory | G14: EV-66.
... A26: N6 | B26: Contract terms | C26: Will the vendor take part in our security awareness and resilience training where required? | D26: Participation in the bank's training on request, up to two sessions a year. | E26: Full | F26: Satisfactory | G26: EV-45.

Sheet Evidence log
A1: Evidence log, follow-up (simulated)
A3: Evidence ID | B3: Evidence item | C3: Provided by | D3: Date | E3: Strength | F3: Covers | G3: Note
A4: EV-26 | B4: Privileged access tool configuration and approval workflow | C4: Vendor X | D4: 9 Nov 2026 | E4: Medium | F4: FU-IAM-01, FU-IAM-02, FU-IAM-05 | G4: Screenshots
A5: EV-27 | B5: 30-day privileged access log extract | C5: Vendor X | D5: Oct to Nov 2026 | E5: Strong | F5: FU-IAM-01 | G5: System export. No standing sessions
A6: EV-28 | B6: Secret read-access list (3 roles) and approval log | C6: Vendor X | D6: Nov 2026 | E6: Strong | F6: FND-01 | G6: Verified by Bank IT security
A7: EV-29 | B7: Credential rotation job configuration and execution log | C7: Vendor X | D7: 14 Nov 2026 | E7: Strong | F7: FU-IAM-03 | G7: First automated rotation
A8: EV-30 | B8: Revocation test record | C8: Observed by Bank IT | D8: 19 Nov 2026 | E8: Strong | F8: FU-IAM-04 | G8: 2 hours 10 minutes
A9: EV-31 | B9: Transfer impact assessments: India support, email provider, monitoring provider | C9: Vendor X | D9: Nov 2026 | E9: Medium | F9: FU-PRV-02 | G9: Vendor-authored, reviewed by the bank's DPO
A10: EV-32 | B10: AI assistant switch-off configuration and test session | C10: Observed by Bank IT | D10: 12 Nov 2026 | E10: Strong | F10: FU-AIS-02 | G10: No calls to the provider seen
A11: EV-33 | B11: Data processing excerpt with the AI model provider | C11: Vendor X | D11: Nov 2026 | E11: Medium | F11: FU-AIS-01 | G11: Full contract withheld
A12: EV-34 | B12: Vendor counter-proposal on audit rights (letter) | C12: Vendor X | D12: 6 Nov 2026 | E12: Strong (document) | F12: FND-05 | G12: Two on-site audits a year, 10 working days' notice
A13: EV-35 | B13: Qualified assessor letter: vendor out of PCI DSS scope (tokens only) | C13: Vendor X | D13: Nov 2026 | E13: Strong | F13: FND-06 | G13: Card Provider Y attestation remains valid (EV-04)
A14: EV-36 | B14: SOC 2 bridge letter, 1 Jan to 30 Sep 2026 | C14: Vendor X | D14: Oct 2026 | E14: Strong | F14: FND-08 | G14: No new exceptions
... A44: EV-66 | B44: Vendor's physical architecture and security specification (submitted, unverified) | C44: Vendor X | D44: 6 Nov 2026 | E44: Medium (vendor-authored) | F44: Many R2 questions | G44: See vendor-physical-architecture

Sheet Bank actions
A1: The bank's own actions (customer-side controls)
A3: ID | B3: Action | C3: Owner | D3: Status | E3: Linked to
A4: BA-01 | B4: Call-back check for any change of the vendor's bank details | C4: Bank Finance | D4: Approved | E4: FND-21
A5: BA-02 | B5: Conditional access and MFA policy for the platform application | C5: Bank IT security | D5: Done | E5: FS, FND-09
A6: BA-03 | B6: Quarterly access review of bank-side booker accounts | C6: Bank HR and IT | D6: Planned | E6: FND-22
A7: BA-04 | B7: Ingest vendor audit events into the bank's SIEM when streaming is available | C7: Bank IT security | D7: Planned (Q1 2027) | E7: FU-MON-03
A8: BA-05 | B8: Weekly review of the allowance rate-table change log | C8: Bank Finance | D8: Started | E8: FND-07
A9: BA-06 | B9: Runbook to disable the connector's service accounts at once | C9: Bank IT security | D9: Drafted | E9: RR-01
A10: BA-07 | B10: Register of information entry and criticality record | C10: Bank Compliance | D10: Drafted | E10: R1
A11: BA-08 | B11: Confirm whether the supervisor must be informed before signing | C11: Bank Compliance | D11: Open | E11: R1
A12: BA-09 | B12: Decision on a data protection impact assessment | C12: Bank DPO | D12: In progress | E12: R2
A13: BA-10 | B13: Review the India transfer assessment | C13: Bank DPO | D13: Reviewed, accepted with the masking condition | E13: FND-03
A14: BA-11 | B14: Assign the 14 SOC 2 customer controls to bank owners | C14: Bank TPRM | D14: Open | E14: FND-28
... A16: BA-13 | B16: Incident contact list agreed with the vendor | C16: Bank TPRM | D16: Done | E16: RR-01

Sheet Outside-in checks
A1: Outside-in checks done by the bank (simulated results)
A3: ID | B3: Check | C3: Result | D3: Outcome
A4: OS-01 | B4: Sanctions and adverse media screening of the legal entity and owners | C4: No matches | D4: Closed
A5: OS-02 | B5: Public TLS configuration of the vendor's endpoints | C5: TLS 1.2 and 1.3 only, HSTS on. Matches the vendor's statement | D5: Closed
A6: OS-03 | B6: Email security records (SPF, DKIM, DMARC) | C6: DMARC set to quarantine, not reject | D6: Observation (Low)
A7: OS-04 | B7: Certificate and domain hygiene | C7: Valid certificates, expiry in 62 days, no unexpected domains | D7: Closed
A8: OS-05 | B8: External security rating | C8: Stable, in the good range (simulated) | D8: Closed
A9: OS-06 | B9: Public breach history, last three years | C9: No public breach. The 2024 incident was not public | D9: Observation
A10: OS-07 | B10: Company registry: ownership and legal entity | C10: Matches the vendor's statements | D10: Closed
A11: OS-08 | B11: Public subprocessor page | C11: Lists 10 suppliers and omits the AI provider | D11: Confirms FND-04
A12: OS-09 | B12: Credit and financial indicators | C12: Low risk (simulated) | D12: Closed
A13: OS-10 | B13: Security contact page (security.txt) | C13: Absent | D13: Confirms FND-33

Sheet Not requested
A1: Not requested, and why
A3: Item | B3: Reason
A4: Source code review or access to repositories | B4: The analyst asks for evidence, not code. Branch rules and scan summaries are enough
A5: Running scans or tests against the vendor | B5: Not an analyst's job and not permitted without agreement. The penetration test letter covers it
A6: On-site visit to the cloud provider's data centres | B6: Controls are inherited. The provider's assurance reports are requested instead
A7: Physical security details of every vendor site | B7: Asked once for the India support site, as an if-applicable item
A8: Environmental, social and diversity reporting | B8: No link to a risk in this case
A9: E-discovery and legal hold procedures | B9: Not relevant to a travel platform. Data return is covered in the contract
A10: Container and Kubernetes configuration exports | B10: Posture report and scan summaries are enough unless a finding points here
A11: Full application security standard verification | B11: Out of proportion for an analyst. Scan, test and review evidence is requested instead
A12: Red team reports | B12: Not expected from a vendor of this kind. Penetration test retest letter requested

Sheet Controls (new)
A1: New control requirements from the follow-up
A3: CR ID | B3: Area | C3: Requirement | D3: Risk addressed | E3: Derived from | F3: Questions | G3: DORA | H3: GDPR | I3: ISO 27001:2022 Annex A | J3: Other | K3: Tier
A4: CR-29 | B4: Secure development | C4: Code is built, reviewed, tested and released under a defined lifecycle with security testing, review rules that administrators cannot bypass, timely fixing of findings and tracked dependencies. | D4: Vulnerable code reaches production | E4: Follow-up items A and B; RR-19 | F4: FU-APP-01, FU-APP-02, FU-APP-03, FU-APP-04, FU-APP-05, FU-APP-06, FU-APP-07, FU-CHG-01 | G4: Art 9; Art 24 | H4: Art 25; Art 32 | I4: A.8.25; A.8.28; A.8.29; A.8.32 | J4: OWASP ASVS (reference) | K4: All tiers
A5: CR-30 | B5: Cloud and network platform security | C5: The vendor's cloud platform is segmented, monitored for misconfiguration, protected at the perimeter and separated by environment, and keeps data in the agreed regions, backups included. | D5: Data leaves the agreed regions or the platform is misconfigured | E5: Follow-up items 1 and 3; V6; RR-18 | F5: FU-CLD-01, FU-CLD-02, FU-CLD-03, FU-CLD-04, FU-NET-01, FU-NET-02, FU-NET-03, FU-INF-01, FU-CHG-02, FU-PHY-01 | G5: Art 9 | H5: Art 32 | I5: A.5.23; A.8.9; A.8.20; A.8.22; A.7.1 | K5: All tiers
A6: CR-31 | B6: Key management | C6: Keys are held in a managed key service with separated custodians, rotated on a schedule, and customer-managed keys are offered for sensitive data. | D6: Keys misused or exposed | E6: Follow-up item 2; RR-20 | F6: FU-CRY-01, FU-CRY-02, FU-DAT-03 | G6: Art 9 | H6: Art 32(1)(a) | I6: A.8.24 | K6: All tiers
A7: CR-32 | B7: People and endpoint security | C7: Staff with access to the bank's data are screened, trained and use protected endpoints, offshore staff included. | D7: Insider misuse or leakage by support staff | E7: Follow-up item 5; RR-21 | F7: FU-PPL-01, FU-PPL-02, FU-PPL-03, FU-DAT-04, FU-PHY-02 | G7: Art 9 | H7: Art 32 | I7: A.6.1; A.6.3; A.8.1; A.7.2 | K7: All tiers
A8: CR-33 | B8: Vendor standing: finance, insurance, liability | C8: Insurance, financial standing and liability terms match the potential loss, and the vendor has an anti-bribery and sanctions policy. | D8: The vendor cannot cover a loss | E8: Follow-up; RR-08 | F8: FU-GRC-02, FU-GRC-03, FU-GRC-04 | G8: Art 28(4); Art 30(2) | H8: Art 28(1) | I8: A.5.22; A.5.31 | J8: Anti-bribery policy (R5) | K8: All tiers
A10: Existing control requirements extended by the follow-up questions
A11: CR ID | C11: Follow-up questions added
A12: CR-04 | C12: FU-IAM-03, FU-IAM-04
A13: CR-09 | C13: FU-IAM-01, FU-IAM-02, FU-IAM-05, FU-INF-02
A14: CR-12 | C14: FU-DAT-01, FU-PRV-03
A15: CR-13 | C15: FU-CRY-03
A16: CR-14 | C16: FU-DAT-02, FU-CLD-03, FU-PRV-01, FU-PRV-02
A17: CR-15 | C17: FU-MON-01, FU-MON-02, FU-MON-03
A18: CR-16 | C18: FU-TPR-01, FU-TPR-02, FU-TPR-03, FU-TPR-04
A19: CR-23 | C19: FU-VUL-01, FU-VUL-02, FU-VUL-03, FU-GRC-01
A20: CR-24 | C20: FU-INC-01, FU-INC-02, FU-INC-03, FU-INC-04, FU-BCD-01, FU-BCD-02, FU-BCD-03, FU-BCD-04
A21: CR-27 | C21: FU-CHG-03
A22: CR-28 | C22: FU-AIS-01, FU-AIS-02, FU-AIS-03, FU-AIS-04

Sheet Regulatory map
A1: Regulatory map, follow-up questions
A2: DORA = Regulation (EU) 2022/2554. GDPR = Regulation (EU) 2016/679. ISO = ISO/IEC 27001:2022 Annex A. Article-level and indicative.
A4: ID | B4: Area | C4: Question | D4: DORA reference | E4: GDPR reference | F4: ISO 27001:2022 Annex A | G4: Other reference
A5: FU-IAM-01 | B5: Identity and access management | C5: How is privileged access to production systems granted (just-in-time, approval, expiry), and how long can a privileged session last? | D5: Art 9 | E5: Art 32 | F5: A.8.2; A.5.18
A6: FU-IAM-02 | B6: Identity and access management | C6: Provide the privileged account inventory and the date of the last privileged access review. | D6: Art 9 | E6: Art 32 | F6: A.8.2; A.5.18
A7: FU-IAM-03 | B7: Identity and access management | C7: How are service accounts and API keys inventoried, owned and rotated? Which belong to the bank's connector? | D7: Art 9 | E7: Art 32 | F7: A.8.2; A.5.18
A8: FU-IAM-04 | B8: Identity and access management | C8: Can the bank revoke the connector's credentials itself, and how fast can the vendor revoke on request? | D8: Art 9 | E8: Art 32 | F8: A.8.2; A.5.18
A9: FU-IAM-05 | B9: Identity and access management | C9: How is segregation of duties enforced for vendor staff who can both deploy code and access production data? | D9: Art 9 | E9: Art 32 | F9: A.8.2; A.5.18
A10: FU-DAT-01 | B10: Data security | C10: Provide the data classification scheme and show how passport data and executive itineraries are labelled and handled. | D10: Art 9 | E10: Art 5(1)(c); Art 32 | F10: A.5.12; A.8.13; A.8.12
A11: FU-DAT-02 | B11: Data security | C11: Provide the record of where each data type is stored and processed, including every location of backups and replicas. | D11: Art 30(2)(b) | E11: Arts 44 to 49 | F11: A.5.34; A.5.12
A12: FU-DAT-03 | B12: Data security | C12: How are backups and snapshots encrypted, and who can restore them? | D12: Art 9 | E12: Art 5(1)(c); Art 32 | F12: A.5.12; A.8.13; A.8.12
A13: FU-DAT-04 | B13: Data security | C13: How do you stop personal data leaving through endpoints and email (data loss prevention)? | D13: Art 9 | E13: Art 5(1)(c); Art 32 | F13: A.5.12; A.8.13; A.8.12
A14: FU-CRY-01 | B14: Cryptography and key management | C14: Who manages the encryption keys for databases and backups, and can the bank use its own keys? | D14: Art 9 | E14: Art 32(1)(a) | F14: A.8.24
A15: FU-CRY-02 | B15: Cryptography and key management | C15: How are key custodians separated, and how often are keys rotated and revoked? | D15: Art 9 | E15: Art 32(1)(a) | F15: A.8.24
A16: FU-CRY-03 | B16: Cryptography and key management | C16: Provide the TLS configuration for public endpoints and for connections to the database and to fourth parties. | D16: Art 9 | E16: Art 32(1)(a) | F16: A.8.24
A17: FU-APP-01 | B17: Application security | C17: Provide the secure development policy and a process diagram showing where security checks occur. | D17: Art 9 | E17: Art 25; Art 32 | F17: A.8.25; A.8.28; A.8.29 | G17: OWASP ASVS (reference)
A18: FU-APP-02 | B18: Application security | C18: Provide the latest static analysis and dependency scan summaries for the platform and the connector, with open High findings and their age. | D18: Art 9 | E18: Art 25; Art 32 | F18: A.8.25; A.8.28; A.8.29 | G18: OWASP ASVS (reference)
A19: FU-APP-03 | B19: Application security | C19: How often is dynamic testing (DAST) run against a staging environment, and what were the last results? | D19: Art 9 | E19: Art 25; Art 32 | F19: A.8.25; A.8.28; A.8.29 | G19: OWASP ASVS (reference)
A20: FU-APP-04 | B20: Application security | C20: Show the branch protection and code review rules for production and infrastructure repositories. | D20: Art 9 | E20: Art 25 | F20: A.8.25; A.8.32; A.8.4 | G20: OWASP ASVS (reference)
A21: FU-APP-05 | B21: Application security | C21: Is automated secret scanning run on code repositories, and how are leaked secrets handled? | D21: Art 9 | E21: Art 25; Art 32 | F21: A.8.25; A.8.28; A.8.29 | G21: OWASP ASVS (reference)
A22: FU-APP-06 | B22: Application security | C22: Provide the software bill of materials, or the list of critical third-party libraries, for the connector and platform. | D22: Art 9 | E22: Art 25; Art 32 | F22: A.8.25; A.8.28; A.8.29 | G22: OWASP ASVS (reference)
A23: FU-APP-07 | B23: Application security | C23: Has a threat model been done for the connector and the support access path, and when was it last updated? | D23: Art 9 | E23: Art 25; Art 32 | F23: A.8.25; A.8.28; A.8.29 | G23: OWASP ASVS (reference)
A24: FU-CLD-01 | B24: Cloud security | C24: Provide the shared-responsibility matrix between the vendor and its cloud provider. | D24: Art 9 | E24: Art 32 | F24: A.5.23; A.8.9
A25: FU-CLD-02 | B25: Cloud security | C25: How is cloud configuration monitored for drift and misconfiguration (posture management)? | D25: Art 9 | E25: Art 32 | F25: A.5.23; A.8.9
A26: FU-CLD-03 | B26: Cloud security | C26: Describe production, standby and backup regions, with a diagram of data replication between them. | D26: Art 30(2)(b) | E26: Arts 44 to 49 | F26: A.5.23; A.5.34
A27: FU-CLD-04 | B27: Cloud security | C27: How are production, staging and development environments separated, and who can access each? | D27: Art 9 | E27: Art 32 | F27: A.5.23; A.8.9
A28: FU-NET-01 | B28: Network security | C28: Provide the network segmentation design: separation of web, application and database tiers, and administrative access. | D28: Art 9 | E28: Art 32 | F28: A.8.20; A.8.22
A29: FU-NET-02 | B29: Network security | C29: Which perimeter controls protect public endpoints (web application firewall, DDoS protection, API gateway, rate limits)? | D29: Art 9 | E29: Art 32 | F29: A.8.20; A.8.22
A30: FU-NET-03 | B30: Network security | C30: How is outbound traffic from production restricted to approved destinations? | D30: Art 9 | E30: Art 32 | F30: A.8.20; A.8.22
A31: FU-TPR-01 | B31: Third-party risk | C31: How do you assess your own suppliers (security review, questionnaire, reassessment), and how often? | D31: Art 28(3); Art 28(4) | E31: Art 28(2); Art 28(4) | F31: A.5.19; A.5.21; A.5.22
