Workbook

Sheet Read me
A1: Assessment workbook (Stage 5, simulated)
A2: Case study | B2: Fictional learning project. Example Bank and Vendor X are placeholders. Not based on any real organisation, vendor or assessment.
A3: Purpose | B3: Stage 4 of the case study. It links each question to a control requirement, to the data flows in the architecture, and to DORA, GDPR and ISO 27001.
A4: Chain | B4: Flow or observation, then risk, then control requirement (CR), then framework reference, then question, then (Stage 5) vendor answer, finding and decision.
A5: Sheets | B5: Stage 4 sheets with simulated answers filled in, plus: Evidence log, Findings, Risk register, Remediation plan and Monitoring. Summary shows the results by domain, findings by severity and risks by band.
A6: Cells to edit | B6: Yellow cells only: vendor details, and the response, evidence status, rating and notes columns on the Questionnaire sheet.
A7: Example row | B7: Row 6 (ID EX) shows the expected format and is not counted in the Summary.
A8: Flow IDs | B8: FS, FA, F3 to F12, FG, FN, FL, FH and FV refer to the data-flow table in Stage 3. All means every flow.
A9: Tier | B9: The service is Tier 1, so every question applies. Questions marked Deeper in the Regulatory map need full depth because the service supports a critical or important function.
A10: Evidence strength | B10: Strong: independent report, or system export or test dated within 90 days. Medium: dated screenshot, or policy with a small sample of records. Weak: policy only, vendor statement, or undated material.
A11: Assessor rating | B11: Satisfactory: control described and supported by strong evidence (or medium for lower-risk controls). Partial: described but evidence is weak or coverage incomplete. Gap: absent or contradicted. Not applicable: does not apply.
A12: ID note | B12: Question IDs are a domain letter plus a number (for example H1). In the traceability matrix they carry the prefix Q-, because D, F, R and S are also used for data, factors, regulations and scope.
A13: Regulatory references | B13: Article-level and indicative. Verify against the official texts. Not legal advice.
... A16: Input cell | B16: Yellow fill: fill this in.

Sheet Summary
A1: Assessment summary
A2: Counts update from the Questionnaire sheet (example row excluded).
A4: Domain | B4: Questions | C4: Satisfactory | D4: Partial | E4: Gap | F4: Not applicable | G4: Not yet rated | H4: Evidence accepted
A5: Scope and service model | B5: =COUNTIF(Questionnaire!$B$7:$B$93,$A5) -> 3 | C5: =COUNTIFS(Questionnaire!$B$7:$B$93,$A5,Questionnaire!$I$7:$I$93,"Satisfactory") -> 0 | D5: =COUNTIFS(Questionnaire!$B$7:$B$93,$A5,Questionnaire!$I$7:$I$93,"Partial") -> 1 | E5: =COUNTIFS(Questionnaire!$B$7:$B$93,$A5,Questionnaire!$I$7:$I$93,"Gap") -> 0 | F5: =COUNTIFS(Questionnaire!$B$7:$B$93,$A5,Questionnaire!$I$7:$I$93,"Not applicable") -> 0 | G5: =B5-SUM(C5:F5) -> 2 | H5: =COUNTIFS(Questionnaire!$B$7:$B$93,$A5,Questionnaire!$H$7:$H$93,"Accepted") -> 0
A6: Identity and sign-on | B6: =COUNTIF(Questionnaire!$B$7:$B$93,$A6) -> 4 | C6: =COUNTIFS(Questionnaire!$B$7:$B$93,$A6,Questionnaire!$I$7:$I$93,"Satisfactory") -> 2 | D6: =COUNTIFS(Questionnaire!$B$7:$B$93,$A6,Questionnaire!$I$7:$I$93,"Partial") -> 1 | E6: =COUNTIFS(Questionnaire!$B$7:$B$93,$A6,Questionnaire!$I$7:$I$93,"Gap") -> 0 | F6: =COUNTIFS(Questionnaire!$B$7:$B$93,$A6,Questionnaire!$I$7:$I$93,"Not applicable") -> 0 | G6: =B6-SUM(C6:F6) -> 1 | H6: =COUNTIFS(Questionnaire!$B$7:$B$93,$A6,Questionnaire!$H$7:$H$93,"Accepted") -> 2
A7: Provisioning and leavers | B7: =COUNTIF(Questionnaire!$B$7:$B$93,$A7) -> 5 | C7: =COUNTIFS(Questionnaire!$B$7:$B$93,$A7,Questionnaire!$I$7:$I$93,"Satisfactory") -> 1 | D7: =COUNTIFS(Questionnaire!$B$7:$B$93,$A7,Questionnaire!$I$7:$I$93,"Partial") -> 1 | E7: =COUNTIFS(Questionnaire!$B$7:$B$93,$A7,Questionnaire!$I$7:$I$93,"Gap") -> 0 | F7: =COUNTIFS(Questionnaire!$B$7:$B$93,$A7,Questionnaire!$I$7:$I$93,"Not applicable") -> 0 | G7: =B7-SUM(C7:F7) -> 3 | H7: =COUNTIFS(Questionnaire!$B$7:$B$93,$A7,Questionnaire!$H$7:$H$93,"Accepted") -> 1
A8: Administration and access | B8: =COUNTIF(Questionnaire!$B$7:$B$93,$A8) -> 5 | C8: =COUNTIFS(Questionnaire!$B$7:$B$93,$A8,Questionnaire!$I$7:$I$93,"Satisfactory") -> 1 | D8: =COUNTIFS(Questionnaire!$B$7:$B$93,$A8,Questionnaire!$I$7:$I$93,"Partial") -> 2 | E8: =COUNTIFS(Questionnaire!$B$7:$B$93,$A8,Questionnaire!$I$7:$I$93,"Gap") -> 2 | F8: =COUNTIFS(Questionnaire!$B$7:$B$93,$A8,Questionnaire!$I$7:$I$93,"Not applicable") -> 0 | G8: =B8-SUM(C8:F8) -> 0 | H8: =COUNTIFS(Questionnaire!$B$7:$B$93,$A8,Questionnaire!$H$7:$H$93,"Accepted") -> 1
A9: HR data sync | B9: =COUNTIF(Questionnaire!$B$7:$B$93,$A9) -> 4 | C9: =COUNTIFS(Questionnaire!$B$7:$B$93,$A9,Questionnaire!$I$7:$I$93,"Satisfactory") -> 1 | D9: =COUNTIFS(Questionnaire!$B$7:$B$93,$A9,Questionnaire!$I$7:$I$93,"Partial") -> 1 | E9: =COUNTIFS(Questionnaire!$B$7:$B$93,$A9,Questionnaire!$I$7:$I$93,"Gap") -> 0 | F9: =COUNTIFS(Questionnaire!$B$7:$B$93,$A9,Questionnaire!$I$7:$I$93,"Not applicable") -> 0 | G9: =B9-SUM(C9:F9) -> 2 | H9: =COUNTIFS(Questionnaire!$B$7:$B$93,$A9,Questionnaire!$H$7:$H$93,"Accepted") -> 1
A10: Approvals and policy | B10: =COUNTIF(Questionnaire!$B$7:$B$93,$A10) -> 4 | C10: =COUNTIFS(Questionnaire!$B$7:$B$93,$A10,Questionnaire!$I$7:$I$93,"Satisfactory") -> 0 | D10: =COUNTIFS(Questionnaire!$B$7:$B$93,$A10,Questionnaire!$I$7:$I$93,"Partial") -> 0 | E10: =COUNTIFS(Questionnaire!$B$7:$B$93,$A10,Questionnaire!$I$7:$I$93,"Gap") -> 0 | F10: =COUNTIFS(Questionnaire!$B$7:$B$93,$A10,Questionnaire!$I$7:$I$93,"Not applicable") -> 0 | G10: =B10-SUM(C10:F10) -> 4 | H10: =COUNTIFS(Questionnaire!$B$7:$B$93,$A10,Questionnaire!$H$7:$H$93,"Accepted") -> 0
A11: Financial sync | B11: =COUNTIF(Questionnaire!$B$7:$B$93,$A11) -> 5 | C11: =COUNTIFS(Questionnaire!$B$7:$B$93,$A11,Questionnaire!$I$7:$I$93,"Satisfactory") -> 2 | D11: =COUNTIFS(Questionnaire!$B$7:$B$93,$A11,Questionnaire!$I$7:$I$93,"Partial") -> 1 | E11: =COUNTIFS(Questionnaire!$B$7:$B$93,$A11,Questionnaire!$I$7:$I$93,"Gap") -> 1 | F11: =COUNTIFS(Questionnaire!$B$7:$B$93,$A11,Questionnaire!$I$7:$I$93,"Not applicable") -> 0 | G11: =B11-SUM(C11:F11) -> 1 | H11: =COUNTIFS(Questionnaire!$B$7:$B$93,$A11,Questionnaire!$H$7:$H$93,"Accepted") -> 2
A12: Network and gateway | B12: =COUNTIF(Questionnaire!$B$7:$B$93,$A12) -> 3 | C12: =COUNTIFS(Questionnaire!$B$7:$B$93,$A12,Questionnaire!$I$7:$I$93,"Satisfactory") -> 1 | D12: =COUNTIFS(Questionnaire!$B$7:$B$93,$A12,Questionnaire!$I$7:$I$93,"Partial") -> 0 | E12: =COUNTIFS(Questionnaire!$B$7:$B$93,$A12,Questionnaire!$I$7:$I$93,"Gap") -> 0 | F12: =COUNTIFS(Questionnaire!$B$7:$B$93,$A12,Questionnaire!$I$7:$I$93,"Not applicable") -> 0 | G12: =B12-SUM(C12:F12) -> 2 | H12: =COUNTIFS(Questionnaire!$B$7:$B$93,$A12,Questionnaire!$H$7:$H$93,"Accepted") -> 1
A13: Data protection | B13: =COUNTIF(Questionnaire!$B$7:$B$93,$A13) -> 8 | C13: =COUNTIFS(Questionnaire!$B$7:$B$93,$A13,Questionnaire!$I$7:$I$93,"Satisfactory") -> 2 | D13: =COUNTIFS(Questionnaire!$B$7:$B$93,$A13,Questionnaire!$I$7:$I$93,"Partial") -> 3 | E13: =COUNTIFS(Questionnaire!$B$7:$B$93,$A13,Questionnaire!$I$7:$I$93,"Gap") -> 1 | F13: =COUNTIFS(Questionnaire!$B$7:$B$93,$A13,Questionnaire!$I$7:$I$93,"Not applicable") -> 0 | G13: =B13-SUM(C13:F13) -> 2 | H13: =COUNTIFS(Questionnaire!$B$7:$B$93,$A13,Questionnaire!$H$7:$H$93,"Accepted") -> 2
A14: Logging and monitoring | B14: =COUNTIF(Questionnaire!$B$7:$B$93,$A14) -> 3 | C14: =COUNTIFS(Questionnaire!$B$7:$B$93,$A14,Questionnaire!$I$7:$I$93,"Satisfactory") -> 1 | D14: =COUNTIFS(Questionnaire!$B$7:$B$93,$A14,Questionnaire!$I$7:$I$93,"Partial") -> 0 | E14: =COUNTIFS(Questionnaire!$B$7:$B$93,$A14,Questionnaire!$I$7:$I$93,"Gap") -> 0 | F14: =COUNTIFS(Questionnaire!$B$7:$B$93,$A14,Questionnaire!$I$7:$I$93,"Not applicable") -> 0 | G14: =B14-SUM(C14:F14) -> 2 | H14: =COUNTIFS(Questionnaire!$B$7:$B$93,$A14,Questionnaire!$H$7:$H$93,"Accepted") -> 1
A15: Subprocessors | B15: =COUNTIF(Questionnaire!$B$7:$B$93,$A15) -> 5 | C15: =COUNTIFS(Questionnaire!$B$7:$B$93,$A15,Questionnaire!$I$7:$I$93,"Satisfactory") -> 0 | D15: =COUNTIFS(Questionnaire!$B$7:$B$93,$A15,Questionnaire!$I$7:$I$93,"Partial") -> 4 | E15: =COUNTIFS(Questionnaire!$B$7:$B$93,$A15,Questionnaire!$I$7:$I$93,"Gap") -> 0 | F15: =COUNTIFS(Questionnaire!$B$7:$B$93,$A15,Questionnaire!$I$7:$I$93,"Not applicable") -> 0 | G15: =B15-SUM(C15:F15) -> 1 | H15: =COUNTIFS(Questionnaire!$B$7:$B$93,$A15,Questionnaire!$H$7:$H$93,"Accepted") -> 0
A16: Assurance | B16: =COUNTIF(Questionnaire!$B$7:$B$93,$A16) -> 3 | C16: =COUNTIFS(Questionnaire!$B$7:$B$93,$A16,Questionnaire!$I$7:$I$93,"Satisfactory") -> 1 | D16: =COUNTIFS(Questionnaire!$B$7:$B$93,$A16,Questionnaire!$I$7:$I$93,"Partial") -> 1 | E16: =COUNTIFS(Questionnaire!$B$7:$B$93,$A16,Questionnaire!$I$7:$I$93,"Gap") -> 0 | F16: =COUNTIFS(Questionnaire!$B$7:$B$93,$A16,Questionnaire!$I$7:$I$93,"Not applicable") -> 0 | G16: =B16-SUM(C16:F16) -> 1 | H16: =COUNTIFS(Questionnaire!$B$7:$B$93,$A16,Questionnaire!$H$7:$H$93,"Accepted") -> 1
... A24: AI and automation | B24: =COUNTIF(Questionnaire!$B$7:$B$93,$A24) -> 3 | C24: =COUNTIFS(Questionnaire!$B$7:$B$93,$A24,Questionnaire!$I$7:$I$93,"Satisfactory") -> 1 | D24: =COUNTIFS(Questionnaire!$B$7:$B$93,$A24,Questionnaire!$I$7:$I$93,"Partial") -> 2 | E24: =COUNTIFS(Questionnaire!$B$7:$B$93,$A24,Questionnaire!$I$7:$I$93,"Gap") -> 0 | F24: =COUNTIFS(Questionnaire!$B$7:$B$93,$A24,Questionnaire!$I$7:$I$93,"Not applicable") -> 0 | G24: =B24-SUM(C24:F24) -> 0 | H24: =COUNTIFS(Questionnaire!$B$7:$B$93,$A24,Questionnaire!$H$7:$H$93,"Accepted") -> 1
A25: Total | B25: =SUM(B5:B24) -> 87 | C25: =SUM(C5:C24) -> 24 | D25: =SUM(D5:D24) -> 32 | E25: =SUM(E5:E24) -> 8 | F25: =SUM(F5:F24) -> 0 | G25: =SUM(G5:G24) -> 23 | H25: =SUM(H5:H24) -> 24
A28: Findings by severity
A29: High | B29: =COUNTIF(Findings!$C$5:$C$26,"High") -> 5
A30: Medium | B30: =COUNTIF(Findings!$C$5:$C$26,"Medium") -> 16
A31: Low | B31: =COUNTIF(Findings!$C$5:$C$26,"Low") -> 1
A32: Total | B32: =SUM(B29:B31) -> 22
A35: Risks by band
A36: Band | B36: Inherent | C36: Current | D36: Target
A37: Very high | B37: ='Risk register'!G26 -> 2 | C37: ='Risk register'!K26 -> 2 | D37: ='Risk register'!O26 -> 0
A38: High | B38: ='Risk register'!G27 -> 9 | C38: ='Risk register'!K27 -> 4 | D38: ='Risk register'!O27 -> 0
A39: Medium | B39: ='Risk register'!G28 -> 6 | C39: ='Risk register'!K28 -> 11 | D39: ='Risk register'!O28 -> 10
A40: Low | B40: ='Risk register'!G29 -> 0 | C40: ='Risk register'!K29 -> 0 | D40: ='Risk register'!O29 -> 7

Sheet Findings
A1: Findings (gap register)
A2: High: could expose bulk personal data, allow fraudulent payment, give unauthorised access into the bank, or leave a mandatory contract term for a critical service unmet. Medium: weakens a control, but another compensates. Low: minor.
A4: Finding ID | B4: Finding | C4: Severity | D4: Questions | E4: Control requirements | F4: Risk | G4: Source | H4: Evidence | I4: What we found | J4: What is required | K4: Remediation | L4: Status
A5: FND-01 | B5: Wide standing access to connector credentials | C5: High | D5: O3, E3 | E5: CR-03 | F5: RR-01 | G5: X2, V7 | H5: EV-06 | I5: 11 vendor staff can read the bank's connector secrets, and break-glass access has no approval step. | J5: Named roles only, just-in-time approval, access logged and reviewed. | K5: REM-01 | L5: Open
A6: FND-02 | B6: Connector credentials rotated only once a year | C6: High | D6: O4 | E6: CR-04 | F6: RR-01 | G6: X2, V7 | H6: EV-06 | I6: Rotation is annual and manual. Revocation takes up to 2 business days. | J6: Rotation at least every 90 days (proposed default) and revocation by the bank within hours. | K6: REM-02 | L6: Open
A7: FND-03 | B7: Standing support access from India with no transfer assessment | C7: High | D7: D2, D4, I2, T1 | E7: CR-09, CR-14 | F7: RR-02 | G7: X5, V6, V8 | H7: EV-09, EV-10 | I7: 22 India-based staff have standing read access to production data. There is no region restriction and no transfer impact assessment. | J7: Just-in-time, case-by-case access, masked data for offshore staff, and a transfer assessment. | K7: REM-03 | L7: Open
A8: FND-04 | B8: Undisclosed AI model provider with US hosting | C8: High | D8: W1, W2, K1, A3 | E8: CR-28, CR-16 | F8: RR-03 | G8: V13, X7 | H8: EV-10, EV-11 | I8: The chat assistant uses a third-party model provider in the US that is not in the fourth-party list. The provider keeps prompts for 30 days. | J8: Disclose and contract the provider, keep personal data out of prompts, confirm retention, and let the bank switch the feature off. | K8: REM-04 | L8: Open
A9: FND-05 | B9: Audit and inspection rights too limited | C9: High | D9: N7 | E9: CR-25 | F9: RR-11 | G9: R1 | H9: EV-12 | I9: One remote audit a year. On-site audit needs 60 days' notice and reasonable cause. | J9: Unrestricted access, inspection and audit rights for the bank and its authorities (DORA Art 30(3)(e)). High under the Stage 5 rule on mandatory contract terms. | K9: REM-05 | L9: Open
A10: FND-06 | B10: Vendor's own PCI DSS attestation missing | C10: Medium | D10: P1, P4 | E10: CR-20 | F10: RR-06 | G10: V3, X11 | H10: EV-04 | I10: Attestation provided for Card Provider Y only. The vendor's own is due Q1 2027. Card reconciliation is manual. | J10: Attestation covering the vendor's role, or written proof that it is out of scope because it holds tokens only. | K10: REM-06 | L10: Open
A11: FND-07 | B11: No four-eyes control on the allowance rate table | C11: Medium | D11: Q1, D3 | E11: CR-18 | F11: RR-05 | G11: X9 | H11: EV-15 | I11: One Finance admin can change and save rates. Changes are logged but not approved. | J11: Second approval for rate changes, a finance-only role and an alert on change. | K11: REM-07 | L11: Open
A12: FND-08 | B12: Assurance reports are outdated or narrow | C12: Medium | D12: L1 | E12: CR-23 | F12: RR-12 | G12: V1, V2 | H12: EV-01, EV-02 | I12: SOC 2 period ended Dec 2025 with no bridge letter. SOC 2 excludes visa, gifts and card modules. ISO scope excludes the India support site. | J12: A bridge letter and a scope covering every module and site used by the bank. | K12: REM-08 | L12: Open
A13: FND-09 | B13: No mutual TLS on bank-facing connections | C13: Medium | D13: O2 | E13: CR-02 | F13: RR-01 | G13: X1, V7 | H13: EV-08 | I13: Mutual TLS is not supported. 15-minute tokens and IP allow-listing compensate. | J13: Mutual TLS, or the compensating controls accepted with Bank IT security sign-off. | K13: REM-09 | L13: Open
A14: FND-10 | B14: Recovery targets not proven | C14: Medium | D14: M1 | E14: CR-24 | F14: RR-07 | G14: V5 | H14: EV-13 | I14: The 2025 failover took 6 hours against a 4-hour target. No 2026 test. | J14: A test that meets the target, repeated yearly. | K14: REM-10 | L14: Open
A15: FND-11 | B15: Guest data kept 24 months without deletion | C15: Medium | D15: I7 | E15: CR-12, CR-21 | F15: RR-09 | G15: X10 | H15: EV-17 | I15: Guest data is kept for 24 months with no automatic deletion. | J15: Automatic deletion shortly after the trip (90 days proposed). | K15: REM-11 | L15: Open
... A23: FND-19 | B23: VIP itineraries visible unmasked to support staff | C23: Medium | D23: D5 | E23: CR-10 | F23: RR-13 | G23: Stage 1 F5 | H23: EV-09 | I23: Support administrators see VIP profiles unmasked. | J23: Masked VIP profiles for support staff and named agents only. | K23: REM-19 | L23: Open
A24: FND-20 | B24: No regional hosting for non-EU staff | C24: Medium | D24: T2 | E24: CR-14 | F24: RR-15 | G24: R9 | I24: Data is hosted only in the EU. | J24: A review of local-law needs per region and a hosting or exclusion decision. | K24: REM-20 | L24: Open
A25: FND-21 | B25: Invoice files not signed and no call-back on bank-detail changes | C25: Medium | D25: G4, G5 | E25: CR-11 | F25: RR-04 | G25: X3 | H25: EV-16 | I25: SFTP with key authentication but unsigned files. Bank-detail changes are accepted by email. | J25: Signed files and a call-back check by the bank's accounts payable. | K25: REM-21 | L25: Open
A26: FND-22 | B26: Minor gaps in loyalty, discount codes and booker access reporting | C26: Low | D26: Q4, Q5, C5 | E26: CR-19, CR-08 | F26: RR-17 | G26: S11 | I26: No access report for loyalty data, no usage monitoring for discount codes, and no report on bank-side booker accounts. | J26: Access and usage reports. | K26: REM-22 | L26: Open

Sheet Risk register
A1: Risk register
A2: Likelihood (L) and impact (I) are scored 1 to 5. Score = L x I. Bands: 1 to 4 Low, 5 to 9 Medium, 10 to 15 High, 16 to 25 Very high. Inherent = before vendor controls. Current = as assessed. Target = after the agreed remediation.
D4: Inherent | H4: Current | L4: Target
A5: Risk ID | B5: Risk | C5: Findings | D5: L | E5: I | F5: Score | G5: Band | H5: L | I5: I | J5: Score | K5: Band | L5: L | M5: I | N5: Score | O5: Band | P5: Treatment | Q5: Owner
A6: RR-01 | B6: Stolen connector credential allows bulk reading of employee data | C6: FND-01, FND-02, FND-09 | D6: 4 | E6: 5 | F6: =D6*E6 -> 20 | G6: =IF(F6>=16,"Very high",IF(F6>=10,"High",IF(F6>=5,"Medium","Low"))) -> Very high | H6: 3 | I6: 5 | J6: =H6*I6 -> 15 | K6: =IF(J6>=16,"Very high",IF(J6>=10,"High",IF(J6>=5,"Medium","Low"))) -> High | L6: 2 | M6: 4 | N6: =L6*M6 -> 8 | O6: =IF(N6>=16,"Very high",IF(N6>=10,"High",IF(N6>=5,"Medium","Low"))) -> Medium | P6: Mitigate | Q6: Bank IT security
A7: RR-02 | B7: Standing support access from India exposes production data, including passport data | C7: FND-03 | D7: 4 | E7: 4 | F7: =D7*E7 -> 16 | G7: =IF(F7>=16,"Very high",IF(F7>=10,"High",IF(F7>=5,"Medium","Low"))) -> Very high | H7: 4 | I7: 4 | J7: =H7*I7 -> 16 | K7: =IF(J7>=16,"Very high",IF(J7>=10,"High",IF(J7>=5,"Medium","Low"))) -> Very high | L7: 2 | M7: 4 | N7: =L7*M7 -> 8 | O7: =IF(N7>=16,"Very high",IF(N7>=10,"High",IF(N7>=5,"Medium","Low"))) -> Medium | P7: Mitigate | Q7: Bank DPO and TPRM
A8: RR-03 | B8: Personal data reaches an undisclosed AI provider in the US | C8: FND-04 | D8: 3 | E8: 4 | F8: =D8*E8 -> 12 | G8: =IF(F8>=16,"Very high",IF(F8>=10,"High",IF(F8>=5,"Medium","Low"))) -> High | H8: 4 | I8: 4 | J8: =H8*I8 -> 16 | K8: =IF(J8>=16,"Very high",IF(J8>=10,"High",IF(J8>=5,"Medium","Low"))) -> Very high | L8: 1 | M8: 4 | N8: =L8*M8 -> 4 | O8: =IF(N8>=16,"Very high",IF(N8>=10,"High",IF(N8>=5,"Medium","Low"))) -> Low | P8: Avoid, then mitigate | Q8: Bank TPRM
A9: RR-04 | B9: Fraudulent or altered invoice reaches the ERP | C9: FND-21 | D9: 3 | E9: 4 | F9: =D9*E9 -> 12 | G9: =IF(F9>=16,"Very high",IF(F9>=10,"High",IF(F9>=5,"Medium","Low"))) -> High | H9: 3 | I9: 3 | J9: =H9*I9 -> 9 | K9: =IF(J9>=16,"Very high",IF(J9>=10,"High",IF(J9>=5,"Medium","Low"))) -> Medium | L9: 2 | M9: 3 | N9: =L9*M9 -> 6 | O9: =IF(N9>=16,"Very high",IF(N9>=10,"High",IF(N9>=5,"Medium","Low"))) -> Medium | P9: Mitigate | Q9: Bank Finance
A10: RR-05 | B10: Fraudulent allowance payments through rate-table changes | C10: FND-07 | D10: 3 | E10: 3 | F10: =D10*E10 -> 9 | G10: =IF(F10>=16,"Very high",IF(F10>=10,"High",IF(F10>=5,"Medium","Low"))) -> Medium | H10: 3 | I10: 3 | J10: =H10*I10 -> 9 | K10: =IF(J10>=16,"Very high",IF(J10>=10,"High",IF(J10>=5,"Medium","Low"))) -> Medium | L10: 1 | M10: 3 | N10: =L10*M10 -> 3 | O10: =IF(N10>=16,"Very high",IF(N10>=10,"High",IF(N10>=5,"Medium","Low"))) -> Low | P10: Mitigate | Q10: Bank Finance
A11: RR-06 | B11: Card misuse or PCI non-compliance | C11: FND-06 | D11: 3 | E11: 4 | F11: =D11*E11 -> 12 | G11: =IF(F11>=16,"Very high",IF(F11>=10,"High",IF(F11>=5,"Medium","Low"))) -> High | H11: 2 | I11: 4 | J11: =H11*I11 -> 8 | K11: =IF(J11>=16,"Very high",IF(J11>=10,"High",IF(J11>=5,"Medium","Low"))) -> Medium | L11: 1 | M11: 4 | N11: =L11*M11 -> 4 | O11: =IF(N11>=16,"Very high",IF(N11>=10,"High",IF(N11>=5,"Medium","Low"))) -> Low | P11: Avoid until attested, then mitigate | Q11: Bank Finance and TPRM
A12: RR-07 | B12: Outage or slow recovery of the platform | C12: FND-10 | D12: 3 | E12: 3 | F12: =D12*E12 -> 9 | G12: =IF(F12>=16,"Very high",IF(F12>=10,"High",IF(F12>=5,"Medium","Low"))) -> Medium | H12: 3 | I12: 3 | J12: =H12*I12 -> 9 | K12: =IF(J12>=16,"Very high",IF(J12>=10,"High",IF(J12>=5,"Medium","Low"))) -> Medium | L12: 2 | M12: 3 | N12: =L12*M12 -> 6 | O12: =IF(N12>=16,"Very high",IF(N12>=10,"High",IF(N12>=5,"Medium","Low"))) -> Medium | P12: Mitigate | Q12: Bank TPRM
A13: RR-08 | B13: Late breach notice and costly incident assistance | C13: FND-16 | D13: 3 | E13: 4 | F13: =D13*E13 -> 12 | G13: =IF(F13>=16,"Very high",IF(F13>=10,"High",IF(F13>=5,"Medium","Low"))) -> High | H13: 3 | I13: 4 | J13: =H13*I13 -> 12 | K13: =IF(J13>=16,"Very high",IF(J13>=10,"High",IF(J13>=5,"Medium","Low"))) -> High | L13: 2 | M13: 3 | N13: =L13*M13 -> 6 | O13: =IF(N13>=16,"Very high",IF(N13>=10,"High",IF(N13>=5,"Medium","Low"))) -> Medium | P13: Transfer (contract) | Q13: Bank Legal
A14: RR-09 | B14: Excess retention and exposure of guest, log and test data | C14: FND-11, FND-13, FND-14 | D14: 4 | E14: 3 | F14: =D14*E14 -> 12 | G14: =IF(F14>=16,"Very high",IF(F14>=10,"High",IF(F14>=5,"Medium","Low"))) -> High | H14: 3 | I14: 3 | J14: =H14*I14 -> 9 | K14: =IF(J14>=16,"Very high",IF(J14>=10,"High",IF(J14>=5,"Medium","Low"))) -> Medium | L14: 2 | M14: 2 | N14: =L14*M14 -> 4 | O14: =IF(N14>=16,"Very high",IF(N14>=10,"High",IF(N14>=5,"Medium","Low"))) -> Low | P14: Mitigate | Q14: Bank DPO
A15: RR-10 | B15: Unseen fourth parties and late notice of change | C15: FND-12 | D15: 4 | E15: 3 | F15: =D15*E15 -> 12 | G15: =IF(F15>=16,"Very high",IF(F15>=10,"High",IF(F15>=5,"Medium","Low"))) -> High | H15: 3 | I15: 3 | J15: =H15*I15 -> 9 | K15: =IF(J15>=16,"Very high",IF(J15>=10,"High",IF(J15>=5,"Medium","Low"))) -> Medium | L15: 3 | M15: 2 | N15: =L15*M15 -> 6 | O15: =IF(N15>=16,"Very high",IF(N15>=10,"High",IF(N15>=5,"Medium","Low"))) -> Medium | P15: Mitigate | Q15: Bank TPRM
A16: RR-11 | B16: No effective audit or exit rights for a critical service | C16: FND-05, FND-15 | D16: 3 | E16: 5 | F16: =D16*E16 -> 15 | G16: =IF(F16>=16,"Very high",IF(F16>=10,"High",IF(F16>=5,"Medium","Low"))) -> High | H16: 3 | I16: 5 | J16: =H16*I16 -> 15 | K16: =IF(J16>=16,"Very high",IF(J16>=10,"High",IF(J16>=5,"Medium","Low"))) -> High | L16: 1 | M16: 5 | N16: =L16*M16 -> 5 | O16: =IF(N16>=16,"Very high",IF(N16>=10,"High",IF(N16>=5,"Medium","Low"))) -> Medium | P16: Transfer (contract) and mitigate | Q16: Bank Legal and Procurement
A17: RR-12 | B17: Reliance on outdated or narrow assurance reports | C17: FND-08 | D17: 3 | E17: 3 | F17: =D17*E17 -> 9 | G17: =IF(F17>=16,"Very high",IF(F17>=10,"High",IF(F17>=5,"Medium","Low"))) -> Medium | H17: 3 | I17: 3 | J17: =H17*I17 -> 9 | K17: =IF(J17>=16,"Very high",IF(J17>=10,"High",IF(J17>=5,"Medium","Low"))) -> Medium | L17: 2 | M17: 3 | N17: =L17*M17 -> 6 | O17: =IF(N17>=16,"Very high",IF(N17>=10,"High",IF(N17>=5,"Medium","Low"))) -> Medium | P17: Mitigate | Q17: Bank TPRM
... A22: RR-17 | B22: Minor misuse of loyalty data, discount codes or booker accounts | C22: FND-22 | D22: 3 | E22: 2 | F22: =D22*E22 -> 6 | G22: =IF(F22>=16,"Very high",IF(F22>=10,"High",IF(F22>=5,"Medium","Low"))) -> Medium | H22: 3 | I22: 2 | J22: =H22*I22 -> 6 | K22: =IF(J22>=16,"Very high",IF(J22>=10,"High",IF(J22>=5,"Medium","Low"))) -> Medium | L22: 2 | M22: 2 | N22: =L22*M22 -> 4 | O22: =IF(N22>=16,"Very high",IF(N22>=10,"High",IF(N22>=5,"Medium","Low"))) -> Low | P22: Accept | Q22: Bank HR
B24: Risks by band
B25: Band | G25: Inherent | K25: Current | O25: Target
B26: Very high | G26: =COUNTIF(G6:G22,"Very high") -> 2 | K26: =COUNTIF(K6:K22,"Very high") -> 2 | O26: =COUNTIF(O6:O22,"Very high") -> 0
B27: High | G27: =COUNTIF(G6:G22,"High") -> 9 | K27: =COUNTIF(K6:K22,"High") -> 4 | O27: =COUNTIF(O6:O22,"High") -> 0
B28: Medium | G28: =COUNTIF(G6:G22,"Medium") -> 6 | K28: =COUNTIF(K6:K22,"Medium") -> 11 | O28: =COUNTIF(O6:O22,"Medium") -> 10
B29: Low | G29: =COUNTIF(G6:G22,"Low") -> 0 | K29: =COUNTIF(K6:K22,"Low") -> 0 | O29: =COUNTIF(O6:O22,"Low") -> 7

Sheet Remediation plan
A1: Remediation plan
A2: Assumed go-live target: 1 Feb 2027. Pre-go-live items are due by 15 Jan 2027 and must be verified before go-live.
A4: Action ID | B4: Finding | C4: Severity | D4: Action | E4: Owner | F4: Due | G4: Type | H4: Evidence to verify | I4: Status | J4: Notes
A5: REM-01 | B5: FND-01 | C5: =INDEX(Findings!$C$5:$C$26,MATCH(B5,Findings!$A$5:$A$26,0)) -> High | D5: Limit secret read access to named roles, require approval for break-glass access, log it and review monthly. | E5: Vendor X security lead | F5: 15 Jan 2027 | G5: Pre-go-live | H5: Updated access list and approval log | I5: Open
A6: REM-02 | B6: FND-02 | C6: =INDEX(Findings!$C$5:$C$26,MATCH(B6,Findings!$A$5:$A$26,0)) -> High | D6: Rotate credentials at least every 90 days, automate it, and give the bank a self-service revoke. | E6: Vendor X security lead | F6: 15 Jan 2027 | G6: Pre-go-live | H6: Rotation record and a revoke test | I6: Open
A7: REM-03 | B7: FND-03 | C7: =INDEX(Findings!$C$5:$C$26,MATCH(B7,Findings!$A$5:$A$26,0)) -> High | D7: Introduce just-in-time approval for production access, mask data for offshore staff, and complete a transfer impact assessment. | E7: Vendor X and Bank DPO | F7: 15 Jan 2027 | G7: Pre-go-live | H7: Access policy, sample approval log, assessment | I7: Open
A8: REM-04 | B8: FND-04 | C8: =INDEX(Findings!$C$5:$C$26,MATCH(B8,Findings!$A$5:$A$26,0)) -> High | D8: Disable the AI assistant for the bank tenant until the provider is contracted, listed as a fourth party and prompts exclude personal data. | E8: Vendor X, approved by Bank TPRM | F8: 15 Jan 2027 | G8: Feature gate | H8: Feature switched off, then provider contract and prompt redaction evidence | I8: Open
A9: REM-05 | B9: FND-05 | C9: =INDEX(Findings!$C$5:$C$26,MATCH(B9,Findings!$A$5:$A$26,0)) -> High | D9: Amend the contract to give the bank and its authorities unrestricted access, inspection and audit rights. | E9: Bank Legal and Procurement | F9: 15 Jan 2027 | G9: Pre-go-live | H9: Signed contract addendum | I9: Open
A10: REM-06 | B10: FND-06 | C10: =INDEX(Findings!$C$5:$C$26,MATCH(B10,Findings!$A$5:$A$26,0)) -> Medium | D10: Obtain the vendor's own attestation or a written scoping statement. Virtual cards stay off until verified. | E10: Vendor X and Bank TPRM | F10: 31 Mar 2027 | G10: Feature gate | H10: Attestation or accepted scoping statement | I10: Open
A11: REM-07 | B11: FND-07 | C11: =INDEX(Findings!$C$5:$C$26,MATCH(B11,Findings!$A$5:$A$26,0)) -> Medium | D11: Add second approval and a finance-only role for rate changes, with an alert. Until then Finance reviews the change log weekly. | E11: Vendor X and Bank Finance | F11: 30 Apr 2027 | G11: Within 90 days | H11: Configuration screenshot and test of a rate change | I11: Open
A12: REM-08 | B12: FND-08 | C12: =INDEX(Findings!$C$5:$C$26,MATCH(B12,Findings!$A$5:$A$26,0)) -> Medium | D12: Provide a bridge letter now. Extend SOC 2 and ISO scope to the visa, gifts, card modules and the India site at the next cycle. | E12: Vendor X | F12: 15 Jan 2027 (letter), 31 Dec 2027 (scope) | G12: Pre-go-live | H12: Bridge letter, later the new reports | I12: Open
A13: REM-09 | B13: FND-09 | C13: =INDEX(Findings!$C$5:$C$26,MATCH(B13,Findings!$A$5:$A$26,0)) -> Medium | D13: Enable mutual TLS, or document the compensating controls with Bank IT security sign-off. | E13: Bank IT security and Vendor X | F13: 30 Apr 2027 | G13: Within 90 days | H13: Configuration or signed acceptance | I13: Open
A14: REM-10 | B14: FND-10 | C14: =INDEX(Findings!$C$5:$C$26,MATCH(B14,Findings!$A$5:$A$26,0)) -> Medium | D14: Repeat the disaster recovery test and meet the 4-hour target. | E14: Vendor X | F14: 30 Apr 2027 | G14: Within 90 days | H14: Test report | I14: Open
A15: REM-11 | B15: FND-11 | C15: =INDEX(Findings!$C$5:$C$26,MATCH(B15,Findings!$A$5:$A$26,0)) -> Medium | D15: Delete guest data automatically 90 days after the trip. The Bank DPO confirms the period. | E15: Vendor X and Bank DPO | F15: 30 Apr 2027 | G15: Within 90 days | H15: Retention setting and deletion log | I15: Open
A16: REM-12 | B16: FND-12 | C16: =INDEX(Findings!$C$5:$C$26,MATCH(B16,Findings!$A$5:$A$26,0)) -> Medium | D16: Contract 30 days' notice and a right to object for every subprocessor change, shorten supplier retention, and correct the roles. | E16: Bank Legal and Bank DPO | F16: 15 Jan 2027 | G16: Pre-go-live | H16: Contract clause and corrected register | I16: Open
... A26: REM-22 | B26: FND-22 | C26: =INDEX(Findings!$C$5:$C$26,MATCH(B26,Findings!$A$5:$A$26,0)) -> Low | D26: Provide access and usage reports for loyalty data, discount codes and bookers. | E26: Vendor X | F26: 31 Jul 2027 | G26: Track | H26: Sample reports | I26: Open

Sheet Monitoring
A1: Monitoring: key risk indicators and reassessment
A3: KRI ID | B3: Indicator | C3: Measure | D3: Green | E3: Amber | F3: Red | G3: Frequency | H3: Owner | I3: Source
A4: KRI-01 | B4: Days since last connector credential rotation | C4: Days | D4: 90 or fewer | E4: 91 to 120 | F4: Over 120 | G4: Monthly | H4: Bank IT security | I4: Vendor rotation record
A5: KRI-02 | B5: Open High findings | C5: Count | D5: 0 | E5: None | F5: 1 or more | G5: Monthly | H5: Bank TPRM | I5: Findings register
A6: KRI-03 | B6: Overdue remediation actions | C6: Count | D6: 0 | E6: 1 to 2 | F6: 3 or more | G6: Monthly | H6: Bank TPRM | I6: Remediation plan
A7: KRI-04 | B7: Production-data sessions from outside the EU without approval | C7: Count per month | D7: 0 | E7: 1 to 5 | F7: Over 5 | G7: Monthly | H7: Bank TPRM | I7: Vendor access logs
A8: KRI-05 | B8: Age of latest SOC 2 or ISO evidence | C8: Months | D8: 12 or fewer | E8: 13 to 15 | F8: Over 15 | G8: Quarterly | H8: Bank TPRM | I8: Reports and certificates
A9: KRI-06 | B9: Platform availability | C9: Percent per month | D9: 99.9 or more | E9: 99.5 to 99.9 | F9: Below 99.5 | G9: Monthly | H9: Business owner (HR) | I9: Vendor service report
A10: KRI-07 | B10: Hours from HR leaver record to access removal | C10: Hours | D10: 24 or fewer | E10: 25 to 48 | F10: Over 48 | G10: Quarterly | H10: Bank IT security | I10: Leaver test sample
A11: KRI-08 | B11: Failed or incomplete nightly syncs | C11: Count per month | D11: 0 | E11: 1 to 2 | F11: 3 or more | G11: Monthly | H11: Bank HR and IT | I11: Sync alerts
A12: KRI-09 | B12: Invoice exceptions (duplicates, altered bank details) | C12: Count per month | D12: 0 | E12: 1 | F12: 2 or more | G12: Monthly | H12: Bank Finance | I12: Accounts payable log
A13: KRI-10 | B13: Allowance rate changes without second approval | C13: Count per month | D13: 0 | E13: None | F13: 1 or more | G13: Monthly | H13: Bank Finance | I13: Rate-table change log
A14: KRI-11 | B14: Subprocessor changes without notice | C14: Count per quarter | D14: 0 | E14: 1 | F14: 2 or more | G14: Quarterly | H14: Bank TPRM | I14: Vendor notices
... A16: KRI-13 | B16: Disaster recovery test result | C16: Result and age | D16: Met target, within 12 months | E16: Older than 12 months | F16: Failed, or older than 18 months | G16: Annual | H16: Bank TPRM | I16: Test report
A19: Reassessment schedule for a Tier 1 vendor
B20: When | C20: What | H20: Owner
B21: Monthly | C21: Review KRIs and open findings | H21: Bank TPRM
B22: Quarterly | C22: Governance meeting with Vendor X: KRIs, incidents, changes, subprocessors | H22: Bank TPRM and business owner
B23: Every 6 months | C23: Mid-year review of remediation and evidence age | H23: Bank TPRM
B24: Annual | C24: Full reassessment of the Tier 1 service, with refreshed evidence | H24: Bank TPRM
B25: On a trigger | C25: Incident at the vendor, change of ownership, new fourth party, new module (for example AI), lapsed certificate, failed audit, or contract renewal | H25: Bank TPRM

Sheet Evidence log
A1: Evidence log
A2: Simulated evidence received from Vendor X. Strength follows the Stage 4 rules.
A4: Evidence ID | B4: Evidence item | C4: Provided by | D4: Date or period | E4: Strength | F4: Questions covered | G4: Note
A5: EV-01 | B5: ISO/IEC 27001:2022 certificate and scope statement | C5: Vendor X | D5: Mar 2024 to Mar 2027 | E5: Strong | F5: L1 | G5: Scope excludes the India support site
A6: EV-02 | B6: SOC 2 Type II report | C6: Vendor X | D6: Period 1 Jan 2025 to 31 Dec 2025 | E6: Strong, but dated | F6: L1 | G6: No bridge letter for 2026. Visa, gifts and card modules excluded
A7: EV-03 | B7: Penetration test summary letter and remediation tracker | C7: Independent test firm, via vendor | D7: Jun 2026 | E7: Strong | F7: L2, I8 | G7: Full report available under NDA
A8: EV-04 | B8: PCI DSS attestation of compliance for Card Provider Y | C8: Vendor X | D8: Mar 2026 | E8: Strong for Card Provider Y only | F8: P1 | G8: Vendor's own attestation not provided
A9: EV-05 | B9: SSO configuration screenshots | C9: Vendor X | D9: Aug 2026 | E9: Medium | F9: B1, B2, B3 | G9: Screenshots, no export
A10: EV-06 | B10: Secrets management procedure, access list and rotation schedule | C10: Vendor X | D10: Sep 2026 | E10: Medium | F10: E3, O3, O4 | G10: Access list names 11 staff. Rotation is annual
A11: EV-07 | B11: Vendor administrator list | C11: Vendor X | D11: Sep 2026 | E11: Medium | F11: D1 | G11: Eight administrators, all with MFA
A12: EV-08 | B12: Static egress IP list and contract annex | C12: Vendor X | D12: Sep 2026 | E12: Strong | F12: H1, O1 | G12: 30 days' notice of change
A13: EV-09 | B13: Support access policy and 90-day access log extract | C13: Vendor X | D13: Jul to Sep 2026 | E13: Medium | F13: D2, D4, I2 | G13: Log shows standing access by India-based staff
A14: EV-10 | B14: Subprocessor list, data-sharing register and transfer register | C14: Vendor X | D14: Sep 2026 | E14: Medium | F14: A3, I2, K1, K3, K5, T1 | G14: Lists 10 fourth parties, no AI provider
A15: EV-11 | B15: AI feature description (vendor email) | C15: Vendor X | D15: Sep 2026 | E15: Weak | F15: A3, K1, W1, W2, W3 | G15: Vendor statement only
... A29: EV-25 | B29: Insurer interface specification | C29: Vendor X | D29: Sep 2026 | E29: Medium | F29: U1 | G29: Schema validation

Sheet Control requirements
A1: Control requirements
A2: Each requirement is derived from the Stage 1 to 3 sources shown. Questions are IDs on the Questionnaire sheet.
A4: CR ID | B4: Area | C4: Requirement | D4: Risk addressed | E4: Derived from | F4: Questions | G4: DORA | H4: GDPR | I4: ISO 27001:2022 Annex A | J4: Other | K4: Tier
A5: CR-01 | B5: Network | C5: The vendor connects to the bank only from a fixed, documented set of source addresses, announced before any change, and the bank allows only those. | D5: An unauthorised party reaches the bank's HR, expense or finance endpoints | E5: X1; FA, F3, F6, F11, F7 | F5: H1, O1 | G5: Art 9 | H5: Art 32 | I5: A.8.20; A.8.22 | K5: All tiers
A6: CR-02 | B6: Connection authentication | C6: Every connection from the vendor into the bank uses mutual TLS or equivalent strong client authentication, with short-lived tokens. | D6: A stolen or replayed credential works from anywhere | E6: X1; V7 | F6: H2, H3, O2 | G6: Art 9 | H6: Art 32 | I6: A.8.5; A.8.24 | K6: All tiers
A7: CR-03 | B7: Credential storage | C7: Credentials the bank gives the vendor (HR, HR portal, expense and ERP accounts) are held in a vault, never in plain text, readable only by named roles, with access logged. | D7: Compromise of one place exposes four bank systems | E7: X2; V7 | F7: E3, O3 | G7: Art 9 | H7: Art 32 | I7: A.5.17; A.8.24 | K7: All tiers
A8: CR-04 | B8: Credential rotation | C8: Credentials are rotated at least every 90 days and after staff or incident triggers, and the bank can revoke them immediately. (90 days is a proposed default.) | D8: A leaked credential stays valid for months | E8: X2; V7 | F8: O4 | G8: Art 9 | H8: Art 32 | I8: A.5.17 | K8: All tiers
A9: CR-05 | B9: Connector isolation | C9: The connector is a dedicated instance for the bank, patched and monitored, with read-only access and only the agreed fields. | D9: Over-broad access allows bulk reading of employee data | E9: X1, X2; FA, F3 | F9: E1, O5, O6 | G9: Art 9 | H9: Art 5(1)(c); Art 32 | I9: A.8.22; A.8.8; A.5.15 | K9: All tiers
A10: CR-06 | B10: Connector exit | C10: At contract end the connector is shut down, credentials are revoked and deleted, and the bank receives evidence. | D10: Residual access after the relationship ends | E10: X2; Tier 1 | F10: M3, O7 | G10: Art 28(8); Art 30(2)(d) | H10: Art 28(3)(g) | I10: A.5.18; A.5.20 | K10: Tier 1
A11: CR-07 | B11: SSO and MFA | C11: Users sign in only through the bank IdP with MFA. Local passwords are disabled, including for admins, except vaulted break-glass accounts. | D11: Account takeover or unmanaged accounts | E11: X4; FS, FG, F10 | F11: B1, B2, B3, B4 | G11: Art 9 | H11: Art 32 | I11: A.5.16; A.5.17; A.8.5 | K11: All tiers
A12: CR-08 | B12: Joiners, movers, leavers | C12: Accounts follow the HR record: leavers lose access within an agreed time, movers get new roles, seats are reclaimed and access is reviewed. | D12: Former employees keep access to travel data and booking rights | E12: FA; FS | F12: C1, C2, C3, C4, C5 | G12: Art 9 | H12: Art 32 | I12: A.5.16; A.5.18; A.6.5 | K12: All tiers
A13: CR-09 | B13: Privileged and support access | C13: Vendor admin and support access to production data is just-in-time, approved, logged and restricted by region. | D13: Misuse or compromise of support accounts exposes passport and executive data | E13: X5; V8; FV | F13: D1, D2, D4 | G13: Art 9 | H13: Art 28(3)(b); Art 32 | I13: A.8.2; A.8.15 | K13: All tiers
A14: CR-10 | B14: VIP protection | C14: Executive and VIP itineraries have restricted visibility and masked trip purposes, including for vendor staff. | D14: Leak of senior management movements | E14: Stage 1 F5; S2 | F14: D5 | G14: Art 9 | H14: Art 32 | I14: A.8.3; A.5.15 | K14: All tiers
A15: CR-11 | B15: Invoice and finance integrity | C15: Invoices are authenticated and tamper-evident, duplicates and alterations are detected, and changes of bank details are verified with the bank. | D15: A fraudulent or altered invoice reaches the ERP | E15: X3; F7, F8 | F15: G1, G2, G3, G4, G5 | G15: Art 9 | H15: n/a | I15: A.8.26; A.8.32 | K15: All tiers
A16: CR-12 | B16: Data minimisation and lifecycle | C16: Only required fields are sent, retention periods are set and deletion is evidenced, test environments hold no real data, and guest data is deleted after the trip. | D16: Over-collection and long retention of passport and personal data | E16: X10; V10; D2, D3, D10 | F16: A2, E1, I3, I4, I5, I7 | G16: Art 30(2)(c); Art 30(2)(d) | H16: Art 5(1)(c); Art 5(1)(e); Art 32 | I16: A.5.34; A.8.10; A.8.33 | K16: All tiers
A17: CR-13 | B17: Encryption | C17: Data is encrypted in transit (TLS 1.2 or higher) and at rest, with defined key management and a customer-managed key option where available. | D17: Data exposed if storage or traffic is intercepted | E17: V11 | F17: H2, I1 | G17: Art 9 | H17: Art 32(1)(a) | I17: A.8.24 | K17: All tiers
A18: CR-14 | B18: Cross-border transfers and regional rules | C18: Every country that can access or receive personal data is listed with a transfer mechanism, regional residency needs are met, and local regulator requests can be supported. | D18: Unlawful transfer or breach of local data laws | E18: X5, X6; V6; R9 | F18: I2, T1, T2, T3 | G18: Art 30(2)(b) | H18: Arts 44 to 49 | I18: A.5.34; A.5.23 | J18: Regional rules (R9) | K18: All tiers
A19: CR-15 | B19: Logging and monitoring | C19: Security events are logged immutably, exportable to the bank's SIEM, free of personal and card data and monitored for anomalies. Failed syncs raise alerts. | D19: Incidents go undetected, or logs leak personal data | E19: X6; FL | F19: E4, I6, J1, J2, J3 | G19: Art 10 | H19: Art 32; Art 33(2) | I19: A.8.15; A.8.16; A.8.11 | K19: All tiers
A20: CR-16 | B20: Fourth-party transparency | C20: The vendor lists each fourth party, the data it receives and its role, gives advance notice of changes with a right to object, and ensures deletion after use. | D20: Data spreads to suppliers the bank cannot see or control | E20: X7, X12; V9; FP1 to FP10 | F20: K1, K2, K3, K4, K5 | G20: Art 28(3); Art 28(4); Art 30(2)(a) | H20: Art 28(2); Art 28(4) | I20: A.5.19; A.5.21; A.5.22 | K20: Tier 1 (deeper)
A21: CR-17 | B21: Insurer hand-off | C21: Data sent to the group insurer is accurate and minimal, health information is protected, and a failed interface is detected. | D21: Wrong or excessive data reaches the insurer, or there is no cover during a trip | E21: X8; F9 | F21: U1, U2, U3 | G21: Art 9; Art 11 | H21: Art 5(1)(d); Art 9; Art 32 | I21: A.8.26; A.5.34; A.5.30 | K21: All tiers
A22: CR-18 | B22: Allowance integrity | C22: Only authorised Finance roles change the rate table, changes are approved and logged, and calculation errors are detected before payment. | D22: Wrong or fraudulent allowance payments | E22: X9; F10, F11 | F22: D3, Q1, Q2 | G22: Art 9 | H22: n/a | I22: A.8.32; A.5.3 | J22: Allowance tax rules (R10) | K22: All tiers
A23: CR-19 | B23: Gifts and loyalty | C23: Gift orders follow value limits and recipient rules with an audit trail. Loyalty data and discount codes are protected from misuse. | D23: Improper gifts and loyalty fraud | E23: S9, S11; F5d | F23: Q3, Q4, Q5 | G23: Art 9 | H23: Art 32 | I23: A.5.3; A.5.15 | J23: Anti-bribery and gifts policy (R5) | K23: All tiers
A24: CR-20 | B24: Virtual cards | C24: Card numbers are held only where PCI DSS applies and is attested, cards are single-use with limits, and transactions are reconciled. | D24: Card misuse or card data exposure | E24: X11; V3; F12 | F24: P1, P2, P3, P4 | G24: Art 9; Art 28(4) | H24: n/a | I24: A.5.22; A.8.24 | J24: PCI DSS (R7) | K24: All tiers
A25: CR-21 | B25: Guest booking control | C25: Only authorised bookers create guest bookings with sponsor approval, and guest data is minimal and short-lived. | D25: Unauthorised bookings and uncontrolled guest data | E25: X10; S5; FG | F25: F4, I7 | G25: Art 9 | H25: Art 5(1)(c); Art 5(1)(e) | I25: A.5.3; A.5.15 | K25: All tiers
A26: CR-22 | B26: Approval integrity | C26: Approval messages are authenticated and cannot be forged or replayed, policy rules are version-controlled, and requesters cannot approve their own trips. | D26: Unapproved trips or spend | E26: F3, F6 | F26: F1, F2, F3 | G26: Art 9 | H26: n/a | I26: A.8.26; A.5.3 | K26: All tiers
A27: CR-23 | B27: Assurance evidence | C27: The vendor provides current independent assurance that covers all modules and sites: SOC 2 with a bridge letter, ISO 27001 scope, penetration test and PCI attestation. | D27: Reliance on claims or outdated reports | E27: V1 to V4 | F27: L1, L2, L3 | G27: Art 28(4); Art 30(3)(d) | H27: Art 28(1); Art 32(1)(d) | I27: A.5.22; A.8.8; A.8.29 | J27: ISO 27001 and SOC 2 (R8) | K27: Tier 1 (deeper)
A28: CR-24 | B28: Resilience and incident support | C28: Recovery targets are met and tested, incidents are notified to the bank within an agreed time, and the vendor assists at no extra cost or a set cost. | D28: A long outage or a late breach notice | E28: V5; Tier 1 | F28: M1, M2, N4 | G28: Art 11; Art 12; Art 17; Art 30(2)(e); Art 30(2)(f); Art 30(3)(a) | H28: Art 32(1)(b); Art 32(1)(c); Art 33(2) | I28: A.5.24; A.5.26; A.5.30; A.8.13; A.8.14 | K28: Tier 1 (deeper)
A29: CR-25 | B29: Contract terms | C29: The contract contains the DORA Art 30(2) terms and, because the service is Tier 1, the Art 30(3) terms, including audit rights and exit. | D29: No legal basis to enforce the controls | E29: R1; Tier 1 | F29: N1, N2, N3, N4, N5, N6, N7 | G29: Art 30(2); Art 30(3); Art 28(7) | H29: Art 28(3) | I29: A.5.20 | K29: Tier 1
A30: CR-26 | B30: Tenant isolation | C30: Customer tenants are logically separated, tested and prevented from accessing each other's data. | D30: One client sees another client's data | E30: V12; F4 | F30: I8 | G30: Art 9 | H30: Art 32 | I30: A.8.3; A.8.22 | K30: All tiers
A31: CR-27 | B31: Architecture transparency | C31: The vendor documents its edition, interfaces and data flows, keeps them current, and tells the bank about changes. | D31: The bank assesses a picture that no longer matches reality | E31: Stage 3; all flows | F31: A1, A3, E2 | G31: Art 8; Art 28(3); Art 30(2)(a) | H31: Art 30 | I31: A.5.9; A.8.20 | K31: All tiers
A32: CR-28 | B32: AI and automation | C32: AI features and model providers are disclosed, bank data is not used for model training unless agreed, and automated actions stay under human control. | D32: Bank data leaks into models, or automated actions go unchecked | E32: AI note; V13 (to add in Stage 2) | F32: W1, W2, W3 | G32: Art 28(3); Art 30(2)(a) | H32: Art 5(1)(b); Art 28(2) | I32: A.5.19; A.5.21; A.8.26 | J32: ISO/IEC 42001, EU AI Act (to check) | K32: All tiers

Sheet Questionnaire
A1: Vendor questionnaire
B2: Vendor | C2: Vendor X (fictional) | D2: Assessor | E2: TPRM learner (author)
B3: Service reviewed | C3: Corporate travel management platform, Tier 1 | D3: Date | E3: 4 Oct 2026
A5: ID | B5: Domain | C5: Question | D5: Flow IDs | E5: Control | F5: Evidence to request | G5: Vendor response | H5: Evidence status | I5: Assessor rating | J5: Assessor notes
A6: EX | B6: Identity and sign-on | C6: Is MFA enforced at the IdP for every login? | D6: FS | E6: CR-07 | F6: MFA policy export | G6: Yes. Enforced through conditional access for all users including admins. Two vaulted break-glass accounts are excluded. | H6: Received | I6: Satisfactory | J6: Policy export dated 15 Sep 2026 reviewed.
A7: A1 | B7: Scope and service model | C7: Is the service multi-tenant SaaS, single-tenant cloud, or self-hosted? Which edition and version are we buying? | D7: All | E7: CR-27 | F7: Architecture overview; order form showing edition | H7: Not requested
A8: A2 | B8: Scope and service model | C8: Which data categories will the service store or process (employee data, passport/ID numbers, financial data)? | D8: All | E8: CR-12 | F8: Data inventory; data-flow diagram | H8: Not requested
A9: A3 | B9: Scope and service model | C9: Which of our systems does the service connect to, and which side initiates each connection? | D9: All | E9: CR-27 | F9: Integration diagram showing trust boundaries | G9: Architecture diagram provided. It shows 10 fourth parties. | H9: Received | I9: Partial | J9: The diagram omits the AI model provider named in W1. EV-10, EV-11. FND-04.
A10: B1 | B10: Identity and sign-on | C10: Does the service support SAML 2.0 or OIDC with our IdP, and is SSO enforced for all users? | D10: FS, FG, F10 | E10: CR-07 | F10: SSO configuration screenshot; enforcement setting | G10: SAML single sign-on is enforced for all customer users. Local password login is disabled. | H10: Accepted | I10: Satisfactory | J10: EV-05.
A11: B2 | B11: Identity and sign-on | C11: Can local username/password login be disabled for every user, including administrators? Which break-glass accounts exist? | D11: FS, FG, F10 | E11: CR-07 | F11: Setting screenshot; list of exceptions | G11: Four vendor-side break-glass admin accounts keep local passwords with a TOTP code. The passwords are not stored in a vault. | H11: Received | I11: Partial | J11: EV-05. FND-18.
A12: B3 | B12: Identity and sign-on | C12: Is MFA enforced at the IdP for every login, and how can we verify it from the service side? | D12: FS, FG, F10 | E12: CR-07 | F12: MFA / conditional access policy export | G12: MFA is enforced at the bank's IdP. The platform rejects sessions that do not come through SSO. | H12: Accepted | I12: Satisfactory | J12: EV-05.
A13: B4 | B13: Identity and sign-on | C13: What session timeout, re-authentication and device or network restrictions apply? | D13: FS, FG, F10 | E13: CR-07 | F13: Session policy settings | H13: Not requested
A14: C1 | B14: Provisioning and leavers | C14: How are accounts created (SCIM, API, manual, self-signup)? Is self-signup disabled? | D14: FA, FS | E14: CR-08 | F14: Provisioning configuration; self-signup setting | H14: Not requested
A15: C2 | B15: Provisioning and leavers | C15: When the HRIS or IdP marks a user inactive, how quickly is access removed in the service? | D15: FA, FS | E15: CR-08 | F15: Leaver test with timestamps | G15: Login stops when the IdP disables the user. Booking rights are removed at the next nightly sync. | H15: Accepted | I15: Satisfactory | J15: Leaver test: 19 hours from HR change to removal. EV-14.
A16: C3 | B16: Provisioning and leavers | C16: How are role changes (movers) reflected in groups, roles and entitlements? | D16: FA | E16: CR-08 | F16: Group-to-role mapping; sample mover record | H16: Not requested
A17: C4 | B17: Provisioning and leavers | C17: How are seats assigned and reclaimed, and are dormant accounts reported? | D17: FS | E17: CR-08 | F17: License report; dormant-account review | H17: Not requested
A18: C5 | B18: Provisioning and leavers | C18: How often are user access reviews performed, and who signs them off? | D18: FS | E18: CR-08 | F18: Last access review record | G18: Vendor admin accounts are reviewed twice a year. The platform cannot report on bank-side booker accounts. | H18: Received | I18: Partial | J18: FND-22 (Low).
A19: D1 | B19: Administration and access | C19: Who holds administrator rights on the vendor side and on our side? Are admin accounts separate, MFA-protected and logged? | D19: FS, FV | E19: CR-09 | F19: Admin list; admin role model | G19: Eight vendor administrators, all with MFA. | H19: Accepted | I19: Satisfactory | J19: EV-07.
A20: D2 | B20: Administration and access | C20: Can vendor support staff access our data? Under what approval, time limit and logging? | D20: FV | E20: CR-09 | F20: Support access policy; sample access log | G20: Support staff in Ireland and India have standing read access to production data through the admin tool. All access is logged. | H20: Rejected | I20: Gap | J20: No just-in-time approval. 22 India-based staff. EV-09. FND-03.
A21: D3 | B21: Administration and access | C21: Can entitlement rules (grade-based travel rules) be changed only by authorized admins, and are changes logged? | D21: F10 | E21: CR-18 | F21: Role matrix; change log extract | G21: Customer admins change entitlement rules in the console. Changes are logged. | H21: Received | I21: Partial | J21: No second approval. See Q1. EV-15. FND-07.
A22: D4 | B22: Administration and access | C22: Is vendor support access to production data from outside the EU (for example from India) restricted, time-limited and approved case by case? | D22: FV | E22: CR-09 | F22: Support access policy; sample access log | G22: No technical restriction by region. A policy asks staff to access data only when needed. | H22: Rejected | I22: Gap | J22: EV-09. FND-03.
A23: D5 | B23: Administration and access | C23: How is visibility of executive and VIP itineraries restricted, including for vendor staff and for bank booker accounts? | D23: FV | E23: CR-10 | F23: VIP profile configuration; access test result | G23: VIP profiles are hidden from standard agents. Support administrators see them unmasked. | H23: Received | I23: Partial | J23: FND-19.
A24: E1 | B24: HR data sync | C24: Which employee fields are received, and are they limited to the minimum needed? | D24: FA, F3 | E24: CR-05, CR-12 | F24: Field mapping / data dictionary | H24: Not requested
A25: E2 | B25: HR data sync | C25: What method (REST, webhook, SFTP) and direction is used, and who initiates the connection? | D25: FA, F3 | E25: CR-27 | F25: Interface specification | H25: Not requested
A26: E3 | B26: HR data sync | C26: How are credentials (API tokens, SFTP keys) stored, scoped and rotated? | D26: FA, F3, F11 | E26: CR-03 | F26: Key management procedure; rotation records | G26: Credentials are stored in the cloud provider's key vault and read by the connector at runtime. | H26: Received | I26: Partial | J26: 11 named staff can read the secret. EV-06. FND-01.
A27: E4 | B27: HR data sync | C27: What happens when a sync fails or sends bad data (alerting, retry, reconciliation)? | D27: FA | E27: CR-15 | F27: Runbook; sample failed-sync alert | G27: Failed nightly syncs raise an alert to bank IT within 1 hour. | H27: Accepted | I27: Satisfactory | J27: Sample alert provided. EV-16.
A28: F1 | B28: Approvals and policy | C28: How are policy rules defined, approved and version-controlled? | D28: F3, F4 | E28: CR-22 | F28: Policy configuration; change approvals | H28: Not requested
A29: F2 | B29: Approvals and policy | C29: How is an approval request authenticated so it cannot be forged or replayed? | D29: F3, F6 | E29: CR-22 | F29: Technical description; pen-test finding summary | H29: Not requested
A30: F3 | B30: Approvals and policy | C30: Is segregation of duties enforced (a requester cannot approve their own booking)? | D30: F3 | E30: CR-22 | F30: Test result or configuration evidence | H30: Not requested
A31: F4 | B31: Approvals and policy | C31: How does the platform stop users who are not authorised bookers from creating bookings, and how is the sponsor's approval enforced for guest travel? | D31: FG | E31: CR-21 | F31: Role configuration; guest booking workflow test | H31: Not requested
A32: G1 | B32: Financial sync | C32: What financial data is sent to our ERP, and does the vendor have only write access to a staging area? | D32: F7, F11 | E32: CR-11 | F32: Interface spec; ERP role scope | G32: Invoices go to an SFTP intake queue. The vendor has no write access to the ERP. | H32: Accepted | I32: Satisfactory | J32: EV-16.
A33: G2 | B33: Financial sync | C33: How are completeness and integrity checked (reconciliation, duplicate detection)? | D33: F7 | E33: CR-11 | F33: Sample reconciliation report | G33: A monthly reconciliation report is produced per cost centre. | H33: Accepted | I33: Satisfactory | J33: EV-16.
A34: G3 | B34: Financial sync | C34: How are payment details and supplier data protected against tampering? | D34: F7, F8 | E34: CR-11 | F34: Change control procedure | H34: Not requested
A35: G4 | B35: Financial sync | C35: How are invoices sent to our ERP authenticated and protected against tampering (for example signing or mutual TLS)? | D35: F7 | E35: CR-11 | F35: Interface specification; security design | G35: SFTP with key-based authentication. The files are not digitally signed. | H35: Received | I35: Partial | J35: EV-16. FND-21.
A36: G5 | B36: Financial sync | C36: How does the vendor detect duplicate or altered invoices before they reach us, and how are changes to its bank details verified with us? | D36: F7 | E36: CR-11 | F36: Procedure; sample control log | G36: Duplicate invoice numbers are rejected. Changes to the vendor's bank details are accepted by email from its finance contact, with no call-back. | H36: Rejected | I36: Gap | J36: The bank's accounts payable needs its own call-back control. EV-16. FND-21.
A37: H1 | B37: Network and gateway | C37: Which IP ranges and domains does the vendor use, and how are changes announced so we can allow-list them? | D37: FA, F3, F6, F11, F7 | E37: CR-01 | F37: IP / domain list; notification process | G37: Two static source IP addresses, one per region. | H37: Accepted | I37: Satisfactory | J37: EV-08.
A38: H2 | B38: Network and gateway | C38: Which TLS versions and cipher policy are used? Is mutual TLS available for APIs? | D38: FA, F3, F6, F11, F7 | E38: CR-02, CR-13 | F38: TLS scan report | H38: Not requested
A39: H3 | B39: Network and gateway | C39: How are APIs authenticated (OAuth, keys), scoped and rate-limited? | D39: FA, F3, F6, F11, F7 | E39: CR-02 | F39: API security documentation | H39: Not requested
A40: I1 | B40: Data protection | C40: How is data encrypted at rest and in transit, who manages keys, and is a customer-managed key option available? | D40: FH | E40: CR-13 | F40: Encryption standard; key management description | G40: AES-256 at rest and TLS 1.2 or higher in transit. Customer-managed keys are not offered. | H40: Accepted | I40: Satisfactory | J40: Acceptable for this tier. EV-21.
A41: I2 | B41: Data protection | C41: In which countries and regions is data hosted and backed up? Are there cross-border transfers? | D41: FV, FN, FL, F5 | E41: CR-14 | F41: Hosting locations; data localization statement | G41: A transfer register is provided: India for support, and US providers FP9 and FP10, all under standard contractual clauses. | H41: Received | I41: Partial | J41: No transfer impact assessment for India. EV-09, EV-10. FND-03.
...

Sheet Regulatory map
A1: Regulatory map
A2: DORA = Regulation (EU) 2022/2554. GDPR = Regulation (EU) 2016/679. ISO = ISO/IEC 27001:2022 Annex A. Other uses the Stage 1 regulation IDs. Article-level and indicative only.
A4: ID | B4: Domain | C4: Question | D4: DORA reference | E4: DORA proportionality | F4: GDPR reference | G4: ISO 27001:2022 Annex A | H4: Other reference
A5: =Questionnaire!A7 -> A1 | B5: =Questionnaire!B7 -> Scope and service model | C5: =Questionnaire!C7 -> Is the service multi-tenant SaaS, single-tenant cloud, or self-hosted? Which edition and version are we buying? | D5: Art 28(4); Art 30(2)(a) | E5: Baseline | F5: Art 28(1) | G5: A.5.21; A.5.23
A6: =Questionnaire!A8 -> A2 | B6: =Questionnaire!B8 -> Scope and service model | C6: =Questionnaire!C8 -> Which data categories will the service store or process (employee data, passport/ID numbers, financial data)? | D6: Art 8; Art 28(3) | E6: Baseline | F6: Art 5(1)(c); Art 30 | G6: A.5.9; A.5.12
A7: =Questionnaire!A9 -> A3 | B7: =Questionnaire!B9 -> Scope and service model | C7: =Questionnaire!C9 -> Which of our systems does the service connect to, and which side initiates each connection? | D7: Art 8; Art 28(3) | E7: Baseline | F7: n/a | G7: A.5.9; A.8.20
A8: =Questionnaire!A10 -> B1 | B8: =Questionnaire!B10 -> Identity and sign-on | C8: =Questionnaire!C10 -> Does the service support SAML 2.0 or OIDC with our IdP, and is SSO enforced for all users? | D8: Art 9 | E8: Baseline | F8: Art 32 | G8: A.5.16; A.8.5
A9: =Questionnaire!A11 -> B2 | B9: =Questionnaire!B11 -> Identity and sign-on | C9: =Questionnaire!C11 -> Can local username/password login be disabled for every user, including administrators? Which break-glass accounts exist? | D9: Art 9 | E9: Baseline | F9: Art 32 | G9: A.5.17; A.8.5
A10: =Questionnaire!A12 -> B3 | B10: =Questionnaire!B12 -> Identity and sign-on | C10: =Questionnaire!C12 -> Is MFA enforced at the IdP for every login, and how can we verify it from the service side? | D10: Art 9 | E10: Baseline | F10: Art 32 | G10: A.8.5
A11: =Questionnaire!A13 -> B4 | B11: =Questionnaire!B13 -> Identity and sign-on | C11: =Questionnaire!C13 -> What session timeout, re-authentication and device or network restrictions apply? | D11: Art 9 | E11: Baseline | F11: Art 32 | G11: A.8.5; A.8.1
A12: =Questionnaire!A14 -> C1 | B12: =Questionnaire!B14 -> Provisioning and leavers | C12: =Questionnaire!C14 -> How are accounts created (SCIM, API, manual, self-signup)? Is self-signup disabled? | D12: Art 9 | E12: Baseline | F12: Art 32 | G12: A.5.16; A.5.18
A13: =Questionnaire!A15 -> C2 | B13: =Questionnaire!B15 -> Provisioning and leavers | C13: =Questionnaire!C15 -> When the HRIS or IdP marks a user inactive, how quickly is access removed in the service? | D13: Art 9 | E13: Baseline | F13: Art 32 | G13: A.5.18; A.6.5
A14: =Questionnaire!A16 -> C3 | B14: =Questionnaire!B16 -> Provisioning and leavers | C14: =Questionnaire!C16 -> How are role changes (movers) reflected in groups, roles and entitlements? | D14: Art 9 | E14: Baseline | F14: Art 32 | G14: A.5.18
A15: =Questionnaire!A17 -> C4 | B15: =Questionnaire!B17 -> Provisioning and leavers | C15: =Questionnaire!C17 -> How are seats assigned and reclaimed, and are dormant accounts reported? | D15: Art 9 | E15: Baseline | F15: n/a | G15: A.5.18
A16: =Questionnaire!A18 -> C5 | B16: =Questionnaire!B18 -> Provisioning and leavers | C16: =Questionnaire!C18 -> How often are user access reviews performed, and who signs them off? | D16: Art 9 | E16: Baseline | F16: Art 32 | G16: A.5.18
